2023-12-01 22:30:14.740 | ERROR    | utils.loggings:exception:40 - (pymysql.err.DataError) (1264, "Out of range value for column 'UserID' at row 1")
[SQL: INSERT INTO users (`UserID`, `UserName`, `RealName`, `Gender`, `IDCard`, `Email`, `Address`, `Account`, `Password`) VALUES (%(UserID)s, %(UserName)s, %(RealName)s, %(Gender)s, %(IDCard)s, %(Email)s, %(Address)s, %(Account)s, %(Password)s)]
[parameters: {'UserID': 202312012230478, 'UserName': None, 'RealName': None, 'Gender': None, 'IDCard': None, 'Email': None, 'Address': None, 'Account': '22', 'Password': '423'}]
(Background on this error at: https://sqlalche.me/e/20/9h9h)
Traceback (most recent call last):

  File "C:\Users\Lenovo\AppData\Local\Programs\Python\Python310\lib\site-packages\sqlalchemy\engine\base.py", line 1969, in _exec_single_context
    self.dialect.do_execute(
    │    │       └ <function DefaultDialect.do_execute at 0x0000023B034F44C0>
    │    └ <sqlalchemy.dialects.mysql.pymysql.MySQLDialect_pymysql object at 0x0000023B038A56F0>
    └ <sqlalchemy.engine.base.Connection object at 0x0000023B051285E0>

  File "C:\Users\Lenovo\AppData\Local\Programs\Python\Python310\lib\site-packages\sqlalchemy\engine\default.py", line 922, in do_execute
    cursor.execute(statement, parameters)
    │      │       │          └ {'UserID': 202312012230478, 'UserName': None, 'RealName': None, 'Gender': None, 'IDCard': None, 'Email': None, 'Address': Non...
    │      │       └ 'INSERT INTO users (`UserID`, `UserName`, `RealName`, `Gender`, `IDCard`, `Email`, `Address`, `Account`, `Password`) VALUES (...
    │      └ <function Cursor.execute at 0x0000023B04A1ADD0>
    └ <pymysql.cursors.Cursor object at 0x0000023B0512BB50>

  File "C:\Users\Lenovo\AppData\Local\Programs\Python\Python310\lib\site-packages\pymysql\cursors.py", line 158, in execute
    result = self._query(query)
             │    │      └ "INSERT INTO users (`UserID`, `UserName`, `RealName`, `Gender`, `IDCard`, `Email`, `Address`, `Account`, `Password`) VALUES (...
             │    └ <function Cursor._query at 0x0000023B04A1B250>
             └ <pymysql.cursors.Cursor object at 0x0000023B0512BB50>

  File "C:\Users\Lenovo\AppData\Local\Programs\Python\Python310\lib\site-packages\pymysql\cursors.py", line 325, in _query
    conn.query(q)
    │    │     └ "INSERT INTO users (`UserID`, `UserName`, `RealName`, `Gender`, `IDCard`, `Email`, `Address`, `Account`, `Password`) VALUES (...
    │    └ <function Connection.query at 0x0000023B04A6A560>
    └ <pymysql.connections.Connection object at 0x0000023B05128A60>

  File "C:\Users\Lenovo\AppData\Local\Programs\Python\Python310\lib\site-packages\pymysql\connections.py", line 549, in query
    self._affected_rows = self._read_query_result(unbuffered=unbuffered)
    │    │                │    │                             └ False
    │    │                │    └ <function Connection._read_query_result at 0x0000023B04A6AB90>
    │    │                └ <pymysql.connections.Connection object at 0x0000023B05128A60>
    │    └ 0
    └ <pymysql.connections.Connection object at 0x0000023B05128A60>

  File "C:\Users\Lenovo\AppData\Local\Programs\Python\Python310\lib\site-packages\pymysql\connections.py", line 779, in _read_query_result
    result.read()
    │      └ <function MySQLResult.read at 0x0000023B04A6B370>
    └ <pymysql.connections.MySQLResult object at 0x0000023B04FF2EF0>

  File "C:\Users\Lenovo\AppData\Local\Programs\Python\Python310\lib\site-packages\pymysql\connections.py", line 1157, in read
    first_packet = self.connection._read_packet()
                   │    └ None
                   └ <pymysql.connections.MySQLResult object at 0x0000023B04FF2EF0>

  File "C:\Users\Lenovo\AppData\Local\Programs\Python\Python310\lib\site-packages\pymysql\connections.py", line 729, in _read_packet
    packet.raise_for_error()
    │      └ <function MysqlPacket.raise_for_error at 0x0000023B04A69120>
    └ <pymysql.protocol.MysqlPacket object at 0x0000023B0512A5F0>

  File "C:\Users\Lenovo\AppData\Local\Programs\Python\Python310\lib\site-packages\pymysql\protocol.py", line 221, in raise_for_error
    err.raise_mysql_exception(self._data)
    │   │                     │    └ <member '_data' of 'MysqlPacket' objects>
    │   │                     └ <pymysql.protocol.MysqlPacket object at 0x0000023B0512A5F0>
    │   └ <function raise_mysql_exception at 0x0000023B03970550>
    └ <module 'pymysql.err' from 'C:\\Users\\Lenovo\\AppData\\Local\\Programs\\Python\\Python310\\lib\\site-packages\\pymysql\\err....

  File "C:\Users\Lenovo\AppData\Local\Programs\Python\Python310\lib\site-packages\pymysql\err.py", line 143, in raise_mysql_exception
    raise errorclass(errno, errval)
          │          │      └ "Out of range value for column 'UserID' at row 1"
          │          └ 1264
          └ <class 'pymysql.err.DataError'>

pymysql.err.DataError: (1264, "Out of range value for column 'UserID' at row 1")


The above exception was the direct cause of the following exception:


Traceback (most recent call last):

  File "E:\pycharm\PyCharm2023.2.4\plugins\python\helpers\pydev\_pydev_bundle\pydev_monkey.py", line 805, in __call__
    ret = self.original_func(*self.args, **self.kwargs)
          │    │              │    │       │    └ {}
          │    │              │    │       └ <_pydev_bundle.pydev_monkey._NewThreadStartupWithTrace object at 0x0000023B0501F940>
          │    │              │    └ ()
          │    │              └ <_pydev_bundle.pydev_monkey._NewThreadStartupWithTrace object at 0x0000023B0501F940>
          │    └ <bound method Thread._bootstrap of <Thread(Thread-5 (serve_forever), started daemon 20884)>>
          └ <_pydev_bundle.pydev_monkey._NewThreadStartupWithTrace object at 0x0000023B0501F940>

  File "C:\Users\Lenovo\AppData\Local\Programs\Python\Python310\lib\threading.py", line 973, in _bootstrap
    self._bootstrap_inner()
    │    └ <function Thread._bootstrap_inner at 0x0000023B7FA8EE60>
    └ <Thread(Thread-5 (serve_forever), started daemon 20884)>

  File "C:\Users\Lenovo\AppData\Local\Programs\Python\Python310\lib\threading.py", line 1016, in _bootstrap_inner
    self.run()
    │    └ <function Thread.run at 0x0000023B7FA8EB90>
    └ <Thread(Thread-5 (serve_forever), started daemon 20884)>

  File "C:\Users\Lenovo\AppData\Local\Programs\Python\Python310\lib\threading.py", line 953, in run
    self._target(*self._args, **self._kwargs)
    │    │        │    │        │    └ {}
    │    │        │    │        └ <Thread(Thread-5 (serve_forever), started daemon 20884)>
    │    │        │    └ ()
    │    │        └ <Thread(Thread-5 (serve_forever), started daemon 20884)>
    │    └ <bound method BaseWSGIServer.serve_forever of <werkzeug.serving.BaseWSGIServer object at 0x0000023B027F1C00>>
    └ <Thread(Thread-5 (serve_forever), started daemon 20884)>

  File "C:\Users\Lenovo\AppData\Local\Programs\Python\Python310\lib\site-packages\werkzeug\serving.py", line 806, in serve_forever
    super().serve_forever(poll_interval=poll_interval)
                                        └ 0.5

  File "C:\Users\Lenovo\AppData\Local\Programs\Python\Python310\lib\socketserver.py", line 237, in serve_forever
    self._handle_request_noblock()
    │    └ <function BaseServer._handle_request_noblock at 0x0000023B001B7E20>
    └ <werkzeug.serving.BaseWSGIServer object at 0x0000023B027F1C00>

  File "C:\Users\Lenovo\AppData\Local\Programs\Python\Python310\lib\socketserver.py", line 316, in _handle_request_noblock
    self.process_request(request, client_address)
    │    │               │        └ ('127.0.0.1', 54320)
    │    │               └ <socket.socket fd=548, family=AddressFamily.AF_INET, type=SocketKind.SOCK_STREAM, proto=0, laddr=('127.0.0.1', 5000), raddr=(...
    │    └ <function BaseServer.process_request at 0x0000023B019D8040>
    └ <werkzeug.serving.BaseWSGIServer object at 0x0000023B027F1C00>

  File "C:\Users\Lenovo\AppData\Local\Programs\Python\Python310\lib\socketserver.py", line 347, in process_request
    self.finish_request(request, client_address)
    │    │              │        └ ('127.0.0.1', 54320)
    │    │              └ <socket.socket fd=548, family=AddressFamily.AF_INET, type=SocketKind.SOCK_STREAM, proto=0, laddr=('127.0.0.1', 5000), raddr=(...
    │    └ <function BaseServer.finish_request at 0x0000023B019D8160>
    └ <werkzeug.serving.BaseWSGIServer object at 0x0000023B027F1C00>

  File "C:\Users\Lenovo\AppData\Local\Programs\Python\Python310\lib\socketserver.py", line 360, in finish_request
    self.RequestHandlerClass(request, client_address, self)
    │    │                   │        │               └ <werkzeug.serving.BaseWSGIServer object at 0x0000023B027F1C00>
    │    │                   │        └ ('127.0.0.1', 54320)
    │    │                   └ <socket.socket fd=548, family=AddressFamily.AF_INET, type=SocketKind.SOCK_STREAM, proto=0, laddr=('127.0.0.1', 5000), raddr=(...
    │    └ <class 'werkzeug.serving.WSGIRequestHandler'>
    └ <werkzeug.serving.BaseWSGIServer object at 0x0000023B027F1C00>

  File "C:\Users\Lenovo\AppData\Local\Programs\Python\Python310\lib\socketserver.py", line 747, in __init__
    self.handle()
    │    └ <function WSGIRequestHandler.handle at 0x0000023B0296D990>
    └ <werkzeug.serving.WSGIRequestHandler object at 0x0000023B0501FBB0>

  File "C:\Users\Lenovo\AppData\Local\Programs\Python\Python310\lib\site-packages\werkzeug\serving.py", line 390, in handle
    super().handle()

  File "C:\Users\Lenovo\AppData\Local\Programs\Python\Python310\lib\http\server.py", line 432, in handle
    self.handle_one_request()
    │    └ <function BaseHTTPRequestHandler.handle_one_request at 0x0000023B019D9870>
    └ <werkzeug.serving.WSGIRequestHandler object at 0x0000023B0501FBB0>

  File "C:\Users\Lenovo\AppData\Local\Programs\Python\Python310\lib\http\server.py", line 420, in handle_one_request
    method()
    └ <bound method WSGIRequestHandler.run_wsgi of <werkzeug.serving.WSGIRequestHandler object at 0x0000023B0501FBB0>>

  File "C:\Users\Lenovo\AppData\Local\Programs\Python\Python310\lib\site-packages\werkzeug\serving.py", line 362, in run_wsgi
    execute(self.server.app)
    │       │    │      └ <werkzeug.debug.DebuggedApplication object at 0x0000023B04FF2B00>
    │       │    └ <werkzeug.serving.BaseWSGIServer object at 0x0000023B027F1C00>
    │       └ <werkzeug.serving.WSGIRequestHandler object at 0x0000023B0501FBB0>
    └ <function WSGIRequestHandler.run_wsgi.<locals>.execute at 0x0000023B050DDAB0>

  File "C:\Users\Lenovo\AppData\Local\Programs\Python\Python310\lib\site-packages\werkzeug\serving.py", line 325, in execute
    for data in application_iter:
                └ <generator object DebuggedApplication.debug_application at 0x0000023B04E9B220>

  File "C:\Users\Lenovo\AppData\Local\Programs\Python\Python310\lib\site-packages\werkzeug\debug\__init__.py", line 330, in debug_application
    app_iter = self.app(environ, start_response)
               │    │   │        └ <function WSGIRequestHandler.run_wsgi.<locals>.start_response at 0x0000023B050DE560>
               │    │   └ {'wsgi.version': (1, 0), 'wsgi.url_scheme': 'http', 'wsgi.input': <_io.BufferedReader name=548>, 'wsgi.errors': <_io.TextIOWr...
               │    └ <Flask 'app'>
               └ <werkzeug.debug.DebuggedApplication object at 0x0000023B04FF2B00>

  File "C:\Users\Lenovo\AppData\Local\Programs\Python\Python310\lib\site-packages\flask\app.py", line 2213, in __call__
    return self.wsgi_app(environ, start_response)
           │    │        │        └ <function WSGIRequestHandler.run_wsgi.<locals>.start_response at 0x0000023B050DE560>
           │    │        └ {'wsgi.version': (1, 0), 'wsgi.url_scheme': 'http', 'wsgi.input': <_io.BufferedReader name=548>, 'wsgi.errors': <_io.TextIOWr...
           │    └ <function Flask.wsgi_app at 0x0000023B02CB3B50>
           └ <Flask 'app'>

  File "C:\Users\Lenovo\AppData\Local\Programs\Python\Python310\lib\site-packages\flask\app.py", line 2190, in wsgi_app
    response = self.full_dispatch_request()
               │    └ <function Flask.full_dispatch_request at 0x0000023B02CB30A0>
               └ <Flask 'app'>

  File "C:\Users\Lenovo\AppData\Local\Programs\Python\Python310\lib\site-packages\flask\app.py", line 1484, in full_dispatch_request
    rv = self.dispatch_request()
         │    └ <function Flask.dispatch_request at 0x0000023B02CB3010>
         └ <Flask 'app'>

  File "C:\Users\Lenovo\AppData\Local\Programs\Python\Python310\lib\site-packages\flask\app.py", line 1469, in dispatch_request
    return self.ensure_sync(self.view_functions[rule.endpoint])(**view_args)
           │    │           │    │              │    │            └ {}
           │    │           │    │              │    └ 'users.register'
           │    │           │    │              └ <Rule '/api_1_0/users/register' (POST, OPTIONS) -> users.register>
           │    │           │    └ {'static': <function Flask.__init__.<locals>.<lambda> at 0x0000023B038B2680>, 'apiversion.Apiversion': <function View.as_view...
           │    │           └ <Flask 'app'>
           │    └ <function Flask.ensure_sync at 0x0000023B02CB32E0>
           └ <Flask 'app'>

  File "C:\Users\Lenovo\PycharmProjects\api_project\api\api_1_0\usersResource\urls.py", line 21, in register
    return UsersOtherResource.register()
           │                  └ <classmethod(<function UsersOtherResource.register at 0x0000023B04FD3D90>)>
           └ <class 'api_1_0.usersResource.usersOtherResource.UsersOtherResource'>

  File "C:\Users\Lenovo\PycharmProjects\api_project\api\api_1_0\usersResource\usersOtherResource.py", line 52, in register
    res = UsersService.register(**kwargs)
          │            │          └ {'account': '22', 'password': '423'}
          │            └ <classmethod(<function UsersService.register at 0x0000023B04FD3010>)>
          └ <class 'service.usersService.UsersService'>

> File "C:\Users\Lenovo\PycharmProjects\api_project\api\service\usersService.py", line 66, in register
    db.session.commit()
    │  │       └ <function scoped_session.commit at 0x0000023B038179A0>
    │  └ <sqlalchemy.orm.scoping.scoped_session object at 0x0000023B02E6C160>
    └ <SQLAlchemy mysql+pymysql://root:***@127.0.0.1:3306/project_1?charset=utf8>

  File "C:\Users\Lenovo\AppData\Local\Programs\Python\Python310\lib\site-packages\sqlalchemy\orm\scoping.py", line 598, in commit
    return self._proxied.commit()
           │    └ <property object at 0x0000023B03825DF0>
           └ <sqlalchemy.orm.scoping.scoped_session object at 0x0000023B02E6C160>

  File "C:\Users\Lenovo\AppData\Local\Programs\Python\Python310\lib\site-packages\sqlalchemy\orm\session.py", line 1969, in commit
    trans.commit(_to_root=True)
    │     └ <function SessionTransaction.commit at 0x0000023B037912D0>
    └ <sqlalchemy.orm.session.SessionTransaction object at 0x0000023B038B7700>

  File "<string>", line 2, in commit

  File "C:\Users\Lenovo\AppData\Local\Programs\Python\Python310\lib\site-packages\sqlalchemy\orm\state_changes.py", line 139, in _go
    ret_value = fn(self, *arg, **kw)
                │  │      │      └ {'_to_root': True}
                │  │      └ ()
                │  └ <sqlalchemy.orm.session.SessionTransaction object at 0x0000023B038B7700>
                └ <function SessionTransaction.commit at 0x0000023B03791240>

  File "C:\Users\Lenovo\AppData\Local\Programs\Python\Python310\lib\site-packages\sqlalchemy\orm\session.py", line 1256, in commit
    self._prepare_impl()
    │    └ <function SessionTransaction._prepare_impl at 0x0000023B037911B0>
    └ <sqlalchemy.orm.session.SessionTransaction object at 0x0000023B038B7700>

  File "<string>", line 2, in _prepare_impl

  File "C:\Users\Lenovo\AppData\Local\Programs\Python\Python310\lib\site-packages\sqlalchemy\orm\state_changes.py", line 139, in _go
    ret_value = fn(self, *arg, **kw)
                │  │      │      └ {}
                │  │      └ ()
                │  └ <sqlalchemy.orm.session.SessionTransaction object at 0x0000023B038B7700>
                └ <function SessionTransaction._prepare_impl at 0x0000023B03791090>

  File "C:\Users\Lenovo\AppData\Local\Programs\Python\Python310\lib\site-packages\sqlalchemy\orm\session.py", line 1231, in _prepare_impl
    self.session.flush()
    │    │       └ <function Session.flush at 0x0000023B03793D90>
    │    └ <sqlalchemy.orm.session.Session object at 0x0000023B05128220>
    └ <sqlalchemy.orm.session.SessionTransaction object at 0x0000023B038B7700>

  File "C:\Users\Lenovo\AppData\Local\Programs\Python\Python310\lib\site-packages\sqlalchemy\orm\session.py", line 4312, in flush
    self._flush(objects)
    │    │      └ None
    │    └ <function Session._flush at 0x0000023B03793F40>
    └ <sqlalchemy.orm.session.Session object at 0x0000023B05128220>

  File "C:\Users\Lenovo\AppData\Local\Programs\Python\Python310\lib\site-packages\sqlalchemy\orm\session.py", line 4447, in _flush
    with util.safe_reraise():
         │    └ <class 'sqlalchemy.util.langhelpers.safe_reraise'>
         └ <module 'sqlalchemy.util' from 'C:\\Users\\Lenovo\\AppData\\Local\\Programs\\Python\\Python310\\lib\\site-packages\\sqlalchem...

  File "C:\Users\Lenovo\AppData\Local\Programs\Python\Python310\lib\site-packages\sqlalchemy\util\langhelpers.py", line 146, in __exit__
    raise exc_value.with_traceback(exc_tb)
          │         │              └ <traceback object at 0x0000023B0518F1C0>
          │         └ <method 'with_traceback' of 'BaseException' objects>
          └ DataError('(pymysql.err.DataError) (1264, "Out of range value for column \'UserID\' at row 1")')

  File "C:\Users\Lenovo\AppData\Local\Programs\Python\Python310\lib\site-packages\sqlalchemy\orm\session.py", line 4408, in _flush
    flush_context.execute()
    │             └ <function UOWTransaction.execute at 0x0000023B03782170>
    └ <sqlalchemy.orm.unitofwork.UOWTransaction object at 0x0000023B0512A9B0>

  File "C:\Users\Lenovo\AppData\Local\Programs\Python\Python310\lib\site-packages\sqlalchemy\orm\unitofwork.py", line 466, in execute
    rec.execute(self)
    │   │       └ <sqlalchemy.orm.unitofwork.UOWTransaction object at 0x0000023B0512A9B0>
    │   └ <function SaveUpdateAll.execute at 0x0000023B03782A70>
    └ SaveUpdateAll(Mapper[Users(users)])

  File "C:\Users\Lenovo\AppData\Local\Programs\Python\Python310\lib\site-packages\sqlalchemy\orm\unitofwork.py", line 642, in execute
    util.preloaded.orm_persistence.save_obj(
    │    │         │               └ <function save_obj at 0x0000023B0376D000>
    │    │         └ <module 'sqlalchemy.orm.persistence' from 'C:\\Users\\Lenovo\\AppData\\Local\\Programs\\Python\\Python310\\lib\\site-packages...
    │    └ <module 'sqlalchemy.util.preloaded' from 'C:\\Users\\Lenovo\\AppData\\Local\\Programs\\Python\\Python310\\lib\\site-packages\...
    └ <module 'sqlalchemy.util' from 'C:\\Users\\Lenovo\\AppData\\Local\\Programs\\Python\\Python310\\lib\\site-packages\\sqlalchem...

  File "C:\Users\Lenovo\AppData\Local\Programs\Python\Python310\lib\site-packages\sqlalchemy\orm\persistence.py", line 93, in save_obj
    _emit_insert_statements(
    └ <function _emit_insert_statements at 0x0000023B0376DA20>

  File "C:\Users\Lenovo\AppData\Local\Programs\Python\Python310\lib\site-packages\sqlalchemy\orm\persistence.py", line 1043, in _emit_insert_statements
    result = connection.execute(
             │          └ <function Connection.execute at 0x0000023B03454DC0>
             └ <sqlalchemy.engine.base.Connection object at 0x0000023B051285E0>

  File "C:\Users\Lenovo\AppData\Local\Programs\Python\Python310\lib\site-packages\sqlalchemy\engine\base.py", line 1416, in execute
    return meth(
           └ <bound method ClauseElement._execute_on_connection of <sqlalchemy.sql.dml.Insert object at 0x0000023B05129DE0>>

  File "C:\Users\Lenovo\AppData\Local\Programs\Python\Python310\lib\site-packages\sqlalchemy\sql\elements.py", line 516, in _execute_on_connection
    return connection._execute_clauseelement(
           │          └ <function Connection._execute_clauseelement at 0x0000023B03455090>
           └ <sqlalchemy.engine.base.Connection object at 0x0000023B051285E0>

  File "C:\Users\Lenovo\AppData\Local\Programs\Python\Python310\lib\site-packages\sqlalchemy\engine\base.py", line 1639, in _execute_clauseelement
    ret = self._execute_context(
          │    └ <function Connection._execute_context at 0x0000023B03455240>
          └ <sqlalchemy.engine.base.Connection object at 0x0000023B051285E0>

  File "C:\Users\Lenovo\AppData\Local\Programs\Python\Python310\lib\site-packages\sqlalchemy\engine\base.py", line 1848, in _execute_context
    return self._exec_single_context(
           │    └ <function Connection._exec_single_context at 0x0000023B034552D0>
           └ <sqlalchemy.engine.base.Connection object at 0x0000023B051285E0>

  File "C:\Users\Lenovo\AppData\Local\Programs\Python\Python310\lib\site-packages\sqlalchemy\engine\base.py", line 1988, in _exec_single_context
    self._handle_dbapi_exception(
    │    └ <function Connection._handle_dbapi_exception at 0x0000023B03455510>
    └ <sqlalchemy.engine.base.Connection object at 0x0000023B051285E0>

  File "C:\Users\Lenovo\AppData\Local\Programs\Python\Python310\lib\site-packages\sqlalchemy\engine\base.py", line 2343, in _handle_dbapi_exception
    raise sqlalchemy_exception.with_traceback(exc_info[2]) from e
          │                    │              │                 └ DataError(1264, "Out of range value for column 'UserID' at row 1")
          │                    │              └ (<class 'pymysql.err.DataError'>, DataError(1264, "Out of range value for column 'UserID' at row 1"), <traceback object at 0x...
          │                    └ <method 'with_traceback' of 'BaseException' objects>
          └ DataError('(pymysql.err.DataError) (1264, "Out of range value for column \'UserID\' at row 1")')

  File "C:\Users\Lenovo\AppData\Local\Programs\Python\Python310\lib\site-packages\sqlalchemy\engine\base.py", line 1969, in _exec_single_context
    self.dialect.do_execute(
    │    │       └ <function DefaultDialect.do_execute at 0x0000023B034F44C0>
    │    └ <sqlalchemy.dialects.mysql.pymysql.MySQLDialect_pymysql object at 0x0000023B038A56F0>
    └ <sqlalchemy.engine.base.Connection object at 0x0000023B051285E0>

  File "C:\Users\Lenovo\AppData\Local\Programs\Python\Python310\lib\site-packages\sqlalchemy\engine\default.py", line 922, in do_execute
    cursor.execute(statement, parameters)
    │      │       │          └ {'UserID': 202312012230478, 'UserName': None, 'RealName': None, 'Gender': None, 'IDCard': None, 'Email': None, 'Address': Non...
    │      │       └ 'INSERT INTO users (`UserID`, `UserName`, `RealName`, `Gender`, `IDCard`, `Email`, `Address`, `Account`, `Password`) VALUES (...
    │      └ <function Cursor.execute at 0x0000023B04A1ADD0>
    └ <pymysql.cursors.Cursor object at 0x0000023B0512BB50>

  File "C:\Users\Lenovo\AppData\Local\Programs\Python\Python310\lib\site-packages\pymysql\cursors.py", line 158, in execute
    result = self._query(query)
             │    │      └ "INSERT INTO users (`UserID`, `UserName`, `RealName`, `Gender`, `IDCard`, `Email`, `Address`, `Account`, `Password`) VALUES (...
             │    └ <function Cursor._query at 0x0000023B04A1B250>
             └ <pymysql.cursors.Cursor object at 0x0000023B0512BB50>

  File "C:\Users\Lenovo\AppData\Local\Programs\Python\Python310\lib\site-packages\pymysql\cursors.py", line 325, in _query
    conn.query(q)
    │    │     └ "INSERT INTO users (`UserID`, `UserName`, `RealName`, `Gender`, `IDCard`, `Email`, `Address`, `Account`, `Password`) VALUES (...
    │    └ <function Connection.query at 0x0000023B04A6A560>
    └ <pymysql.connections.Connection object at 0x0000023B05128A60>

  File "C:\Users\Lenovo\AppData\Local\Programs\Python\Python310\lib\site-packages\pymysql\connections.py", line 549, in query
    self._affected_rows = self._read_query_result(unbuffered=unbuffered)
    │    │                │    │                             └ False
    │    │                │    └ <function Connection._read_query_result at 0x0000023B04A6AB90>
    │    │                └ <pymysql.connections.Connection object at 0x0000023B05128A60>
    │    └ 0
    └ <pymysql.connections.Connection object at 0x0000023B05128A60>

  File "C:\Users\Lenovo\AppData\Local\Programs\Python\Python310\lib\site-packages\pymysql\connections.py", line 779, in _read_query_result
    result.read()
    │      └ <function MySQLResult.read at 0x0000023B04A6B370>
    └ <pymysql.connections.MySQLResult object at 0x0000023B04FF2EF0>

  File "C:\Users\Lenovo\AppData\Local\Programs\Python\Python310\lib\site-packages\pymysql\connections.py", line 1157, in read
    first_packet = self.connection._read_packet()
                   │    └ None
                   └ <pymysql.connections.MySQLResult object at 0x0000023B04FF2EF0>

  File "C:\Users\Lenovo\AppData\Local\Programs\Python\Python310\lib\site-packages\pymysql\connections.py", line 729, in _read_packet
    packet.raise_for_error()
    │      └ <function MysqlPacket.raise_for_error at 0x0000023B04A69120>
    └ <pymysql.protocol.MysqlPacket object at 0x0000023B0512A5F0>

  File "C:\Users\Lenovo\AppData\Local\Programs\Python\Python310\lib\site-packages\pymysql\protocol.py", line 221, in raise_for_error
    err.raise_mysql_exception(self._data)
    │   │                     │    └ <member '_data' of 'MysqlPacket' objects>
    │   │                     └ <pymysql.protocol.MysqlPacket object at 0x0000023B0512A5F0>
    │   └ <function raise_mysql_exception at 0x0000023B03970550>
    └ <module 'pymysql.err' from 'C:\\Users\\Lenovo\\AppData\\Local\\Programs\\Python\\Python310\\lib\\site-packages\\pymysql\\err....

  File "C:\Users\Lenovo\AppData\Local\Programs\Python\Python310\lib\site-packages\pymysql\err.py", line 143, in raise_mysql_exception
    raise errorclass(errno, errval)
          │          │      └ "Out of range value for column 'UserID' at row 1"
          │          └ 1264
          └ <class 'pymysql.err.DataError'>

sqlalchemy.exc.DataError: (pymysql.err.DataError) (1264, "Out of range value for column 'UserID' at row 1")
[SQL: INSERT INTO users (`UserID`, `UserName`, `RealName`, `Gender`, `IDCard`, `Email`, `Address`, `Account`, `Password`) VALUES (%(UserID)s, %(UserName)s, %(RealName)s, %(Gender)s, %(IDCard)s, %(Email)s, %(Address)s, %(Account)s, %(Password)s)]
[parameters: {'UserID': 202312012230478, 'UserName': None, 'RealName': None, 'Gender': None, 'IDCard': None, 'Email': None, 'Address': None, 'Account': '22', 'Password': '423'}]
(Background on this error at: https://sqlalche.me/e/20/9h9h)
2023-12-01 22:32:49.319 | ERROR    | utils.loggings:exception:40 - (pymysql.err.DataError) (1264, "Out of range value for column 'UserID' at row 1")
[SQL: INSERT INTO users (`UserID`, `UserName`, `RealName`, `Gender`, `IDCard`, `Email`, `Address`, `Account`, `Password`) VALUES (%(UserID)s, %(UserName)s, %(RealName)s, %(Gender)s, %(IDCard)s, %(Email)s, %(Address)s, %(Account)s, %(Password)s)]
[parameters: {'UserID': 2023120122328719, 'UserName': None, 'RealName': None, 'Gender': None, 'IDCard': None, 'Email': None, 'Address': None, 'Account': '22', 'Password': '423'}]
(Background on this error at: https://sqlalche.me/e/20/9h9h)
Traceback (most recent call last):

  File "C:\Users\Lenovo\AppData\Local\Programs\Python\Python310\lib\site-packages\sqlalchemy\engine\base.py", line 1969, in _exec_single_context
    self.dialect.do_execute(
    │    │       └ <function DefaultDialect.do_execute at 0x000001DB208BBE20>
    │    └ <sqlalchemy.dialects.mysql.pymysql.MySQLDialect_pymysql object at 0x000001DB20C7DF90>
    └ <sqlalchemy.engine.base.Connection object at 0x000001DB213E11E0>

  File "C:\Users\Lenovo\AppData\Local\Programs\Python\Python310\lib\site-packages\sqlalchemy\engine\default.py", line 922, in do_execute
    cursor.execute(statement, parameters)
    │      │       │          └ {'UserID': 2023120122328719, 'UserName': None, 'RealName': None, 'Gender': None, 'IDCard': None, 'Email': None, 'Address': No...
    │      │       └ 'INSERT INTO users (`UserID`, `UserName`, `RealName`, `Gender`, `IDCard`, `Email`, `Address`, `Account`, `Password`) VALUES (...
    │      └ <function Cursor.execute at 0x000001DB20E3EDD0>
    └ <pymysql.cursors.Cursor object at 0x000001DB213E2890>

  File "C:\Users\Lenovo\AppData\Local\Programs\Python\Python310\lib\site-packages\pymysql\cursors.py", line 158, in execute
    result = self._query(query)
             │    │      └ "INSERT INTO users (`UserID`, `UserName`, `RealName`, `Gender`, `IDCard`, `Email`, `Address`, `Account`, `Password`) VALUES (...
             │    └ <function Cursor._query at 0x000001DB20E3F250>
             └ <pymysql.cursors.Cursor object at 0x000001DB213E2890>

  File "C:\Users\Lenovo\AppData\Local\Programs\Python\Python310\lib\site-packages\pymysql\cursors.py", line 325, in _query
    conn.query(q)
    │    │     └ "INSERT INTO users (`UserID`, `UserName`, `RealName`, `Gender`, `IDCard`, `Email`, `Address`, `Account`, `Password`) VALUES (...
    │    └ <function Connection.query at 0x000001DB20E6E290>
    └ <pymysql.connections.Connection object at 0x000001DB213E18D0>

  File "C:\Users\Lenovo\AppData\Local\Programs\Python\Python310\lib\site-packages\pymysql\connections.py", line 549, in query
    self._affected_rows = self._read_query_result(unbuffered=unbuffered)
    │    │                │    │                             └ False
    │    │                │    └ <function Connection._read_query_result at 0x000001DB20E6E8C0>
    │    │                └ <pymysql.connections.Connection object at 0x000001DB213E18D0>
    │    └ 0
    └ <pymysql.connections.Connection object at 0x000001DB213E18D0>

  File "C:\Users\Lenovo\AppData\Local\Programs\Python\Python310\lib\site-packages\pymysql\connections.py", line 779, in _read_query_result
    result.read()
    │      └ <function MySQLResult.read at 0x000001DB20E6F0A0>
    └ <pymysql.connections.MySQLResult object at 0x000001DB213E2800>

  File "C:\Users\Lenovo\AppData\Local\Programs\Python\Python310\lib\site-packages\pymysql\connections.py", line 1157, in read
    first_packet = self.connection._read_packet()
                   │    └ None
                   └ <pymysql.connections.MySQLResult object at 0x000001DB213E2800>

  File "C:\Users\Lenovo\AppData\Local\Programs\Python\Python310\lib\site-packages\pymysql\connections.py", line 729, in _read_packet
    packet.raise_for_error()
    │      └ <function MysqlPacket.raise_for_error at 0x000001DB20E6CEE0>
    └ <pymysql.protocol.MysqlPacket object at 0x000001DB213E1F60>

  File "C:\Users\Lenovo\AppData\Local\Programs\Python\Python310\lib\site-packages\pymysql\protocol.py", line 221, in raise_for_error
    err.raise_mysql_exception(self._data)
    │   │                     │    └ <member '_data' of 'MysqlPacket' objects>
    │   │                     └ <pymysql.protocol.MysqlPacket object at 0x000001DB213E1F60>
    │   └ <function raise_mysql_exception at 0x000001DB20D38D30>
    └ <module 'pymysql.err' from 'C:\\Users\\Lenovo\\AppData\\Local\\Programs\\Python\\Python310\\lib\\site-packages\\pymysql\\err....

  File "C:\Users\Lenovo\AppData\Local\Programs\Python\Python310\lib\site-packages\pymysql\err.py", line 143, in raise_mysql_exception
    raise errorclass(errno, errval)
          │          │      └ "Out of range value for column 'UserID' at row 1"
          │          └ 1264
          └ <class 'pymysql.err.DataError'>

pymysql.err.DataError: (1264, "Out of range value for column 'UserID' at row 1")


The above exception was the direct cause of the following exception:


Traceback (most recent call last):

  File "C:\Users\Lenovo\AppData\Local\Programs\Python\Python310\lib\threading.py", line 973, in _bootstrap
    self._bootstrap_inner()
    │    └ <function Thread._bootstrap_inner at 0x000001DB1D13E710>
    └ <Thread(Thread-1 (serve_forever), started daemon 24464)>

  File "C:\Users\Lenovo\AppData\Local\Programs\Python\Python310\lib\threading.py", line 1016, in _bootstrap_inner
    self.run()
    │    └ <function Thread.run at 0x000001DB1D13E440>
    └ <Thread(Thread-1 (serve_forever), started daemon 24464)>

  File "C:\Users\Lenovo\AppData\Local\Programs\Python\Python310\lib\threading.py", line 953, in run
    self._target(*self._args, **self._kwargs)
    │    │        │    │        │    └ {}
    │    │        │    │        └ <Thread(Thread-1 (serve_forever), started daemon 24464)>
    │    │        │    └ ()
    │    │        └ <Thread(Thread-1 (serve_forever), started daemon 24464)>
    │    └ <bound method BaseWSGIServer.serve_forever of <werkzeug.serving.BaseWSGIServer object at 0x000001DB213926E0>>
    └ <Thread(Thread-1 (serve_forever), started daemon 24464)>

  File "C:\Users\Lenovo\AppData\Local\Programs\Python\Python310\lib\site-packages\werkzeug\serving.py", line 806, in serve_forever
    super().serve_forever(poll_interval=poll_interval)
                                        └ 0.5

  File "C:\Users\Lenovo\AppData\Local\Programs\Python\Python310\lib\socketserver.py", line 237, in serve_forever
    self._handle_request_noblock()
    │    └ <function BaseServer._handle_request_noblock at 0x000001DB1D13FE20>
    └ <werkzeug.serving.BaseWSGIServer object at 0x000001DB213926E0>

  File "C:\Users\Lenovo\AppData\Local\Programs\Python\Python310\lib\socketserver.py", line 316, in _handle_request_noblock
    self.process_request(request, client_address)
    │    │               │        └ ('127.0.0.1', 54663)
    │    │               └ <socket.socket fd=932, family=AddressFamily.AF_INET, type=SocketKind.SOCK_STREAM, proto=0, laddr=('127.0.0.1', 5000), raddr=(...
    │    └ <function BaseServer.process_request at 0x000001DB1D144040>
    └ <werkzeug.serving.BaseWSGIServer object at 0x000001DB213926E0>

  File "C:\Users\Lenovo\AppData\Local\Programs\Python\Python310\lib\socketserver.py", line 347, in process_request
    self.finish_request(request, client_address)
    │    │              │        └ ('127.0.0.1', 54663)
    │    │              └ <socket.socket fd=932, family=AddressFamily.AF_INET, type=SocketKind.SOCK_STREAM, proto=0, laddr=('127.0.0.1', 5000), raddr=(...
    │    └ <function BaseServer.finish_request at 0x000001DB1D144160>
    └ <werkzeug.serving.BaseWSGIServer object at 0x000001DB213926E0>

  File "C:\Users\Lenovo\AppData\Local\Programs\Python\Python310\lib\socketserver.py", line 360, in finish_request
    self.RequestHandlerClass(request, client_address, self)
    │    │                   │        │               └ <werkzeug.serving.BaseWSGIServer object at 0x000001DB213926E0>
    │    │                   │        └ ('127.0.0.1', 54663)
    │    │                   └ <socket.socket fd=932, family=AddressFamily.AF_INET, type=SocketKind.SOCK_STREAM, proto=0, laddr=('127.0.0.1', 5000), raddr=(...
    │    └ <class 'werkzeug.serving.WSGIRequestHandler'>
    └ <werkzeug.serving.BaseWSGIServer object at 0x000001DB213926E0>

  File "C:\Users\Lenovo\AppData\Local\Programs\Python\Python310\lib\socketserver.py", line 747, in __init__
    self.handle()
    │    └ <function WSGIRequestHandler.handle at 0x000001DB1EEE0790>
    └ <werkzeug.serving.WSGIRequestHandler object at 0x000001DB213E0970>

  File "C:\Users\Lenovo\AppData\Local\Programs\Python\Python310\lib\site-packages\werkzeug\serving.py", line 390, in handle
    super().handle()

  File "C:\Users\Lenovo\AppData\Local\Programs\Python\Python310\lib\http\server.py", line 432, in handle
    self.handle_one_request()
    │    └ <function BaseHTTPRequestHandler.handle_one_request at 0x000001DB1ED257E0>
    └ <werkzeug.serving.WSGIRequestHandler object at 0x000001DB213E0970>

  File "C:\Users\Lenovo\AppData\Local\Programs\Python\Python310\lib\http\server.py", line 420, in handle_one_request
    method()
    └ <bound method WSGIRequestHandler.run_wsgi of <werkzeug.serving.WSGIRequestHandler object at 0x000001DB213E0970>>

  File "C:\Users\Lenovo\AppData\Local\Programs\Python\Python310\lib\site-packages\werkzeug\serving.py", line 362, in run_wsgi
    execute(self.server.app)
    │       │    │      └ <werkzeug.debug.DebuggedApplication object at 0x000001DB21390F40>
    │       │    └ <werkzeug.serving.BaseWSGIServer object at 0x000001DB213926E0>
    │       └ <werkzeug.serving.WSGIRequestHandler object at 0x000001DB213E0970>
    └ <function WSGIRequestHandler.run_wsgi.<locals>.execute at 0x000001DB213EB5B0>

  File "C:\Users\Lenovo\AppData\Local\Programs\Python\Python310\lib\site-packages\werkzeug\serving.py", line 325, in execute
    for data in application_iter:
                └ <generator object DebuggedApplication.debug_application at 0x000001DB2133E570>

  File "C:\Users\Lenovo\AppData\Local\Programs\Python\Python310\lib\site-packages\werkzeug\debug\__init__.py", line 330, in debug_application
    app_iter = self.app(environ, start_response)
               │    │   │        └ <function WSGIRequestHandler.run_wsgi.<locals>.start_response at 0x000001DB213EAE60>
               │    │   └ {'wsgi.version': (1, 0), 'wsgi.url_scheme': 'http', 'wsgi.input': <_io.BufferedReader name=932>, 'wsgi.errors': <_io.TextIOWr...
               │    └ <Flask 'app'>
               └ <werkzeug.debug.DebuggedApplication object at 0x000001DB21390F40>

  File "C:\Users\Lenovo\AppData\Local\Programs\Python\Python310\lib\site-packages\flask\app.py", line 2213, in __call__
    return self.wsgi_app(environ, start_response)
           │    │        │        └ <function WSGIRequestHandler.run_wsgi.<locals>.start_response at 0x000001DB213EAE60>
           │    │        └ {'wsgi.version': (1, 0), 'wsgi.url_scheme': 'http', 'wsgi.input': <_io.BufferedReader name=932>, 'wsgi.errors': <_io.TextIOWr...
           │    └ <function Flask.wsgi_app at 0x000001DB1F787F40>
           └ <Flask 'app'>

  File "C:\Users\Lenovo\AppData\Local\Programs\Python\Python310\lib\site-packages\flask\app.py", line 2190, in wsgi_app
    response = self.full_dispatch_request()
               │    └ <function Flask.full_dispatch_request at 0x000001DB1F787490>
               └ <Flask 'app'>

  File "C:\Users\Lenovo\AppData\Local\Programs\Python\Python310\lib\site-packages\flask\app.py", line 1484, in full_dispatch_request
    rv = self.dispatch_request()
         │    └ <function Flask.dispatch_request at 0x000001DB1F787400>
         └ <Flask 'app'>

  File "C:\Users\Lenovo\AppData\Local\Programs\Python\Python310\lib\site-packages\flask\app.py", line 1469, in dispatch_request
    return self.ensure_sync(self.view_functions[rule.endpoint])(**view_args)
           │    │           │    │              │    │            └ {}
           │    │           │    │              │    └ 'users.register'
           │    │           │    │              └ <Rule '/api_1_0/users/register' (OPTIONS, POST) -> users.register>
           │    │           │    └ {'static': <function Flask.__init__.<locals>.<lambda> at 0x000001DB20C8AF80>, 'apiversion.Apiversion': <function View.as_view...
           │    │           └ <Flask 'app'>
           │    └ <function Flask.ensure_sync at 0x000001DB1F7876D0>
           └ <Flask 'app'>

  File "C:\Users\Lenovo\PycharmProjects\api_project\api\api_1_0\usersResource\urls.py", line 21, in register
    return UsersOtherResource.register()
           │                  └ <classmethod(<function UsersOtherResource.register at 0x000001DB21366DD0>)>
           └ <class 'api_1_0.usersResource.usersOtherResource.UsersOtherResource'>

  File "C:\Users\Lenovo\PycharmProjects\api_project\api\api_1_0\usersResource\usersOtherResource.py", line 52, in register
    res = UsersService.register(**kwargs)
          │            │          └ {'account': '22', 'password': '423'}
          │            └ <classmethod(<function UsersService.register at 0x000001DB21366050>)>
          └ <class 'service.usersService.UsersService'>

> File "C:\Users\Lenovo\PycharmProjects\api_project\api\service\usersService.py", line 66, in register
    db.session.commit()
    │  │       └ <function scoped_session.commit at 0x000001DB20BDF250>
    │  └ <sqlalchemy.orm.scoping.scoped_session object at 0x000001DB1F7C3100>
    └ <SQLAlchemy mysql+pymysql://root:***@127.0.0.1:3306/project_1?charset=utf8>

  File "C:\Users\Lenovo\AppData\Local\Programs\Python\Python310\lib\site-packages\sqlalchemy\orm\scoping.py", line 598, in commit
    return self._proxied.commit()
           │    └ <property object at 0x000001DB20C04EA0>
           └ <sqlalchemy.orm.scoping.scoped_session object at 0x000001DB1F7C3100>

  File "C:\Users\Lenovo\AppData\Local\Programs\Python\Python310\lib\site-packages\sqlalchemy\orm\session.py", line 1969, in commit
    trans.commit(_to_root=True)
    │     └ <function SessionTransaction.commit at 0x000001DB20B68B80>
    └ <sqlalchemy.orm.session.SessionTransaction object at 0x000001DB213B0780>

  File "<string>", line 2, in commit

  File "C:\Users\Lenovo\AppData\Local\Programs\Python\Python310\lib\site-packages\sqlalchemy\orm\state_changes.py", line 139, in _go
    ret_value = fn(self, *arg, **kw)
                │  │      │      └ {'_to_root': True}
                │  │      └ ()
                │  └ <sqlalchemy.orm.session.SessionTransaction object at 0x000001DB213B0780>
                └ <function SessionTransaction.commit at 0x000001DB20B68AF0>

  File "C:\Users\Lenovo\AppData\Local\Programs\Python\Python310\lib\site-packages\sqlalchemy\orm\session.py", line 1256, in commit
    self._prepare_impl()
    │    └ <function SessionTransaction._prepare_impl at 0x000001DB20B68A60>
    └ <sqlalchemy.orm.session.SessionTransaction object at 0x000001DB213B0780>

  File "<string>", line 2, in _prepare_impl

  File "C:\Users\Lenovo\AppData\Local\Programs\Python\Python310\lib\site-packages\sqlalchemy\orm\state_changes.py", line 139, in _go
    ret_value = fn(self, *arg, **kw)
                │  │      │      └ {}
                │  │      └ ()
                │  └ <sqlalchemy.orm.session.SessionTransaction object at 0x000001DB213B0780>
                └ <function SessionTransaction._prepare_impl at 0x000001DB20B68940>

  File "C:\Users\Lenovo\AppData\Local\Programs\Python\Python310\lib\site-packages\sqlalchemy\orm\session.py", line 1231, in _prepare_impl
    self.session.flush()
    │    │       └ <function Session.flush at 0x000001DB20B6B640>
    │    └ <sqlalchemy.orm.session.Session object at 0x000001DB213E0FA0>
    └ <sqlalchemy.orm.session.SessionTransaction object at 0x000001DB213B0780>

  File "C:\Users\Lenovo\AppData\Local\Programs\Python\Python310\lib\site-packages\sqlalchemy\orm\session.py", line 4312, in flush
    self._flush(objects)
    │    │      └ None
    │    └ <function Session._flush at 0x000001DB20B6B7F0>
    └ <sqlalchemy.orm.session.Session object at 0x000001DB213E0FA0>

  File "C:\Users\Lenovo\AppData\Local\Programs\Python\Python310\lib\site-packages\sqlalchemy\orm\session.py", line 4447, in _flush
    with util.safe_reraise():
         │    └ <class 'sqlalchemy.util.langhelpers.safe_reraise'>
         └ <module 'sqlalchemy.util' from 'C:\\Users\\Lenovo\\AppData\\Local\\Programs\\Python\\Python310\\lib\\site-packages\\sqlalchem...

  File "C:\Users\Lenovo\AppData\Local\Programs\Python\Python310\lib\site-packages\sqlalchemy\util\langhelpers.py", line 146, in __exit__
    raise exc_value.with_traceback(exc_tb)
          │         │              └ <traceback object at 0x000001DB214D0940>
          │         └ <method 'with_traceback' of 'BaseException' objects>
          └ DataError('(pymysql.err.DataError) (1264, "Out of range value for column \'UserID\' at row 1")')

  File "C:\Users\Lenovo\AppData\Local\Programs\Python\Python310\lib\site-packages\sqlalchemy\orm\session.py", line 4408, in _flush
    flush_context.execute()
    │             └ <function UOWTransaction.execute at 0x000001DB20B49A20>
    └ <sqlalchemy.orm.unitofwork.UOWTransaction object at 0x000001DB213E28F0>

  File "C:\Users\Lenovo\AppData\Local\Programs\Python\Python310\lib\site-packages\sqlalchemy\orm\unitofwork.py", line 466, in execute
    rec.execute(self)
    │   │       └ <sqlalchemy.orm.unitofwork.UOWTransaction object at 0x000001DB213E28F0>
    │   └ <function SaveUpdateAll.execute at 0x000001DB20B4A320>
    └ SaveUpdateAll(Mapper[Users(users)])

  File "C:\Users\Lenovo\AppData\Local\Programs\Python\Python310\lib\site-packages\sqlalchemy\orm\unitofwork.py", line 642, in execute
    util.preloaded.orm_persistence.save_obj(
    │    │         │               └ <function save_obj at 0x000001DB20B348B0>
    │    │         └ <module 'sqlalchemy.orm.persistence' from 'C:\\Users\\Lenovo\\AppData\\Local\\Programs\\Python\\Python310\\lib\\site-packages...
    │    └ <module 'sqlalchemy.util.preloaded' from 'C:\\Users\\Lenovo\\AppData\\Local\\Programs\\Python\\Python310\\lib\\site-packages\...
    └ <module 'sqlalchemy.util' from 'C:\\Users\\Lenovo\\AppData\\Local\\Programs\\Python\\Python310\\lib\\site-packages\\sqlalchem...

  File "C:\Users\Lenovo\AppData\Local\Programs\Python\Python310\lib\site-packages\sqlalchemy\orm\persistence.py", line 93, in save_obj
    _emit_insert_statements(
    └ <function _emit_insert_statements at 0x000001DB20B352D0>

  File "C:\Users\Lenovo\AppData\Local\Programs\Python\Python310\lib\site-packages\sqlalchemy\orm\persistence.py", line 1043, in _emit_insert_statements
    result = connection.execute(
             │          └ <function Connection.execute at 0x000001DB200389D0>
             └ <sqlalchemy.engine.base.Connection object at 0x000001DB213E11E0>

  File "C:\Users\Lenovo\AppData\Local\Programs\Python\Python310\lib\site-packages\sqlalchemy\engine\base.py", line 1416, in execute
    return meth(
           └ <bound method ClauseElement._execute_on_connection of <sqlalchemy.sql.dml.Insert object at 0x000001DB213E35B0>>

  File "C:\Users\Lenovo\AppData\Local\Programs\Python\Python310\lib\site-packages\sqlalchemy\sql\elements.py", line 516, in _execute_on_connection
    return connection._execute_clauseelement(
           │          └ <function Connection._execute_clauseelement at 0x000001DB20038CA0>
           └ <sqlalchemy.engine.base.Connection object at 0x000001DB213E11E0>

  File "C:\Users\Lenovo\AppData\Local\Programs\Python\Python310\lib\site-packages\sqlalchemy\engine\base.py", line 1639, in _execute_clauseelement
    ret = self._execute_context(
          │    └ <function Connection._execute_context at 0x000001DB20038E50>
          └ <sqlalchemy.engine.base.Connection object at 0x000001DB213E11E0>

  File "C:\Users\Lenovo\AppData\Local\Programs\Python\Python310\lib\site-packages\sqlalchemy\engine\base.py", line 1848, in _execute_context
    return self._exec_single_context(
           │    └ <function Connection._exec_single_context at 0x000001DB20038EE0>
           └ <sqlalchemy.engine.base.Connection object at 0x000001DB213E11E0>

  File "C:\Users\Lenovo\AppData\Local\Programs\Python\Python310\lib\site-packages\sqlalchemy\engine\base.py", line 1988, in _exec_single_context
    self._handle_dbapi_exception(
    │    └ <function Connection._handle_dbapi_exception at 0x000001DB20039120>
    └ <sqlalchemy.engine.base.Connection object at 0x000001DB213E11E0>

  File "C:\Users\Lenovo\AppData\Local\Programs\Python\Python310\lib\site-packages\sqlalchemy\engine\base.py", line 2343, in _handle_dbapi_exception
    raise sqlalchemy_exception.with_traceback(exc_info[2]) from e
          │                    │              │                 └ DataError(1264, "Out of range value for column 'UserID' at row 1")
          │                    │              └ (<class 'pymysql.err.DataError'>, DataError(1264, "Out of range value for column 'UserID' at row 1"), <traceback object at 0x...
          │                    └ <method 'with_traceback' of 'BaseException' objects>
          └ DataError('(pymysql.err.DataError) (1264, "Out of range value for column \'UserID\' at row 1")')

  File "C:\Users\Lenovo\AppData\Local\Programs\Python\Python310\lib\site-packages\sqlalchemy\engine\base.py", line 1969, in _exec_single_context
    self.dialect.do_execute(
    │    │       └ <function DefaultDialect.do_execute at 0x000001DB208BBE20>
    │    └ <sqlalchemy.dialects.mysql.pymysql.MySQLDialect_pymysql object at 0x000001DB20C7DF90>
    └ <sqlalchemy.engine.base.Connection object at 0x000001DB213E11E0>

  File "C:\Users\Lenovo\AppData\Local\Programs\Python\Python310\lib\site-packages\sqlalchemy\engine\default.py", line 922, in do_execute
    cursor.execute(statement, parameters)
    │      │       │          └ {'UserID': 2023120122328719, 'UserName': None, 'RealName': None, 'Gender': None, 'IDCard': None, 'Email': None, 'Address': No...
    │      │       └ 'INSERT INTO users (`UserID`, `UserName`, `RealName`, `Gender`, `IDCard`, `Email`, `Address`, `Account`, `Password`) VALUES (...
    │      └ <function Cursor.execute at 0x000001DB20E3EDD0>
    └ <pymysql.cursors.Cursor object at 0x000001DB213E2890>

  File "C:\Users\Lenovo\AppData\Local\Programs\Python\Python310\lib\site-packages\pymysql\cursors.py", line 158, in execute
    result = self._query(query)
             │    │      └ "INSERT INTO users (`UserID`, `UserName`, `RealName`, `Gender`, `IDCard`, `Email`, `Address`, `Account`, `Password`) VALUES (...
             │    └ <function Cursor._query at 0x000001DB20E3F250>
             └ <pymysql.cursors.Cursor object at 0x000001DB213E2890>

  File "C:\Users\Lenovo\AppData\Local\Programs\Python\Python310\lib\site-packages\pymysql\cursors.py", line 325, in _query
    conn.query(q)
    │    │     └ "INSERT INTO users (`UserID`, `UserName`, `RealName`, `Gender`, `IDCard`, `Email`, `Address`, `Account`, `Password`) VALUES (...
    │    └ <function Connection.query at 0x000001DB20E6E290>
    └ <pymysql.connections.Connection object at 0x000001DB213E18D0>

  File "C:\Users\Lenovo\AppData\Local\Programs\Python\Python310\lib\site-packages\pymysql\connections.py", line 549, in query
    self._affected_rows = self._read_query_result(unbuffered=unbuffered)
    │    │                │    │                             └ False
    │    │                │    └ <function Connection._read_query_result at 0x000001DB20E6E8C0>
    │    │                └ <pymysql.connections.Connection object at 0x000001DB213E18D0>
    │    └ 0
    └ <pymysql.connections.Connection object at 0x000001DB213E18D0>

  File "C:\Users\Lenovo\AppData\Local\Programs\Python\Python310\lib\site-packages\pymysql\connections.py", line 779, in _read_query_result
    result.read()
    │      └ <function MySQLResult.read at 0x000001DB20E6F0A0>
    └ <pymysql.connections.MySQLResult object at 0x000001DB213E2800>

  File "C:\Users\Lenovo\AppData\Local\Programs\Python\Python310\lib\site-packages\pymysql\connections.py", line 1157, in read
    first_packet = self.connection._read_packet()
                   │    └ None
                   └ <pymysql.connections.MySQLResult object at 0x000001DB213E2800>

  File "C:\Users\Lenovo\AppData\Local\Programs\Python\Python310\lib\site-packages\pymysql\connections.py", line 729, in _read_packet
    packet.raise_for_error()
    │      └ <function MysqlPacket.raise_for_error at 0x000001DB20E6CEE0>
    └ <pymysql.protocol.MysqlPacket object at 0x000001DB213E1F60>

  File "C:\Users\Lenovo\AppData\Local\Programs\Python\Python310\lib\site-packages\pymysql\protocol.py", line 221, in raise_for_error
    err.raise_mysql_exception(self._data)
    │   │                     │    └ <member '_data' of 'MysqlPacket' objects>
    │   │                     └ <pymysql.protocol.MysqlPacket object at 0x000001DB213E1F60>
    │   └ <function raise_mysql_exception at 0x000001DB20D38D30>
    └ <module 'pymysql.err' from 'C:\\Users\\Lenovo\\AppData\\Local\\Programs\\Python\\Python310\\lib\\site-packages\\pymysql\\err....

  File "C:\Users\Lenovo\AppData\Local\Programs\Python\Python310\lib\site-packages\pymysql\err.py", line 143, in raise_mysql_exception
    raise errorclass(errno, errval)
          │          │      └ "Out of range value for column 'UserID' at row 1"
          │          └ 1264
          └ <class 'pymysql.err.DataError'>

sqlalchemy.exc.DataError: (pymysql.err.DataError) (1264, "Out of range value for column 'UserID' at row 1")
[SQL: INSERT INTO users (`UserID`, `UserName`, `RealName`, `Gender`, `IDCard`, `Email`, `Address`, `Account`, `Password`) VALUES (%(UserID)s, %(UserName)s, %(RealName)s, %(Gender)s, %(IDCard)s, %(Email)s, %(Address)s, %(Account)s, %(Password)s)]
[parameters: {'UserID': 2023120122328719, 'UserName': None, 'RealName': None, 'Gender': None, 'IDCard': None, 'Email': None, 'Address': None, 'Account': '22', 'Password': '423'}]
(Background on this error at: https://sqlalche.me/e/20/9h9h)
2023-12-01 22:34:30.041 | ERROR    | utils.loggings:exception:40 - (pymysql.err.DataError) (1264, "Out of range value for column 'UserID' at row 1")
[SQL: INSERT INTO users (`UserID`, `UserName`, `RealName`, `Gender`, `IDCard`, `Email`, `Address`, `Account`, `Password`) VALUES (%(UserID)s, %(UserName)s, %(RealName)s, %(Gender)s, %(IDCard)s, %(Email)s, %(Address)s, %(Account)s, %(Password)s)]
[parameters: {'UserID': 2023120122346132, 'UserName': None, 'RealName': None, 'Gender': None, 'IDCard': None, 'Email': None, 'Address': None, 'Account': '22', 'Password': '423'}]
(Background on this error at: https://sqlalche.me/e/20/9h9h)
Traceback (most recent call last):

  File "C:\Users\Lenovo\AppData\Local\Programs\Python\Python310\lib\site-packages\sqlalchemy\engine\base.py", line 1969, in _exec_single_context
    self.dialect.do_execute(
    │    │       └ <function DefaultDialect.do_execute at 0x000001C692F944C0>
    │    └ <sqlalchemy.dialects.mysql.pymysql.MySQLDialect_pymysql object at 0x000001C6933456F0>
    └ <sqlalchemy.engine.base.Connection object at 0x000001C694BC45E0>

  File "C:\Users\Lenovo\AppData\Local\Programs\Python\Python310\lib\site-packages\sqlalchemy\engine\default.py", line 922, in do_execute
    cursor.execute(statement, parameters)
    │      │       │          └ {'UserID': 2023120122346132, 'UserName': None, 'RealName': None, 'Gender': None, 'IDCard': None, 'Email': None, 'Address': No...
    │      │       └ 'INSERT INTO users (`UserID`, `UserName`, `RealName`, `Gender`, `IDCard`, `Email`, `Address`, `Account`, `Password`) VALUES (...
    │      └ <function Cursor.execute at 0x000001C6934EADD0>
    └ <pymysql.cursors.Cursor object at 0x000001C694BC7B80>

  File "C:\Users\Lenovo\AppData\Local\Programs\Python\Python310\lib\site-packages\pymysql\cursors.py", line 158, in execute
    result = self._query(query)
             │    │      └ "INSERT INTO users (`UserID`, `UserName`, `RealName`, `Gender`, `IDCard`, `Email`, `Address`, `Account`, `Password`) VALUES (...
             │    └ <function Cursor._query at 0x000001C6934EB250>
             └ <pymysql.cursors.Cursor object at 0x000001C694BC7B80>

  File "C:\Users\Lenovo\AppData\Local\Programs\Python\Python310\lib\site-packages\pymysql\cursors.py", line 325, in _query
    conn.query(q)
    │    │     └ "INSERT INTO users (`UserID`, `UserName`, `RealName`, `Gender`, `IDCard`, `Email`, `Address`, `Account`, `Password`) VALUES (...
    │    └ <function Connection.query at 0x000001C693536560>
    └ <pymysql.connections.Connection object at 0x000001C694BC4A60>

  File "C:\Users\Lenovo\AppData\Local\Programs\Python\Python310\lib\site-packages\pymysql\connections.py", line 549, in query
    self._affected_rows = self._read_query_result(unbuffered=unbuffered)
    │    │                │    │                             └ False
    │    │                │    └ <function Connection._read_query_result at 0x000001C693536B90>
    │    │                └ <pymysql.connections.Connection object at 0x000001C694BC4A60>
    │    └ 0
    └ <pymysql.connections.Connection object at 0x000001C694BC4A60>

  File "C:\Users\Lenovo\AppData\Local\Programs\Python\Python310\lib\site-packages\pymysql\connections.py", line 779, in _read_query_result
    result.read()
    │      └ <function MySQLResult.read at 0x000001C693537370>
    └ <pymysql.connections.MySQLResult object at 0x000001C694A92EF0>

  File "C:\Users\Lenovo\AppData\Local\Programs\Python\Python310\lib\site-packages\pymysql\connections.py", line 1157, in read
    first_packet = self.connection._read_packet()
                   │    └ None
                   └ <pymysql.connections.MySQLResult object at 0x000001C694A92EF0>

  File "C:\Users\Lenovo\AppData\Local\Programs\Python\Python310\lib\site-packages\pymysql\connections.py", line 729, in _read_packet
    packet.raise_for_error()
    │      └ <function MysqlPacket.raise_for_error at 0x000001C693535120>
    └ <pymysql.protocol.MysqlPacket object at 0x000001C694BC65F0>

  File "C:\Users\Lenovo\AppData\Local\Programs\Python\Python310\lib\site-packages\pymysql\protocol.py", line 221, in raise_for_error
    err.raise_mysql_exception(self._data)
    │   │                     │    └ <member '_data' of 'MysqlPacket' objects>
    │   │                     └ <pymysql.protocol.MysqlPacket object at 0x000001C694BC65F0>
    │   └ <function raise_mysql_exception at 0x000001C693410550>
    └ <module 'pymysql.err' from 'C:\\Users\\Lenovo\\AppData\\Local\\Programs\\Python\\Python310\\lib\\site-packages\\pymysql\\err....

  File "C:\Users\Lenovo\AppData\Local\Programs\Python\Python310\lib\site-packages\pymysql\err.py", line 143, in raise_mysql_exception
    raise errorclass(errno, errval)
          │          │      └ "Out of range value for column 'UserID' at row 1"
          │          └ 1264
          └ <class 'pymysql.err.DataError'>

pymysql.err.DataError: (1264, "Out of range value for column 'UserID' at row 1")


The above exception was the direct cause of the following exception:


Traceback (most recent call last):

  File "E:\pycharm\PyCharm2023.2.4\plugins\python\helpers\pydev\_pydev_bundle\pydev_monkey.py", line 805, in __call__
    ret = self.original_func(*self.args, **self.kwargs)
          │    │              │    │       │    └ {}
          │    │              │    │       └ <_pydev_bundle.pydev_monkey._NewThreadStartupWithTrace object at 0x000001C694AC3940>
          │    │              │    └ ()
          │    │              └ <_pydev_bundle.pydev_monkey._NewThreadStartupWithTrace object at 0x000001C694AC3940>
          │    └ <bound method Thread._bootstrap of <Thread(Thread-5 (serve_forever), started daemon 24544)>>
          └ <_pydev_bundle.pydev_monkey._NewThreadStartupWithTrace object at 0x000001C694AC3940>

  File "C:\Users\Lenovo\AppData\Local\Programs\Python\Python310\lib\threading.py", line 973, in _bootstrap
    self._bootstrap_inner()
    │    └ <function Thread._bootstrap_inner at 0x000001C68F53EE60>
    └ <Thread(Thread-5 (serve_forever), started daemon 24544)>

  File "C:\Users\Lenovo\AppData\Local\Programs\Python\Python310\lib\threading.py", line 1016, in _bootstrap_inner
    self.run()
    │    └ <function Thread.run at 0x000001C68F53EB90>
    └ <Thread(Thread-5 (serve_forever), started daemon 24544)>

  File "C:\Users\Lenovo\AppData\Local\Programs\Python\Python310\lib\threading.py", line 953, in run
    self._target(*self._args, **self._kwargs)
    │    │        │    │        │    └ {}
    │    │        │    │        └ <Thread(Thread-5 (serve_forever), started daemon 24544)>
    │    │        │    └ ()
    │    │        └ <Thread(Thread-5 (serve_forever), started daemon 24544)>
    │    └ <bound method BaseWSGIServer.serve_forever of <werkzeug.serving.BaseWSGIServer object at 0x000001C692291C00>>
    └ <Thread(Thread-5 (serve_forever), started daemon 24544)>

  File "C:\Users\Lenovo\AppData\Local\Programs\Python\Python310\lib\site-packages\werkzeug\serving.py", line 806, in serve_forever
    super().serve_forever(poll_interval=poll_interval)
                                        └ 0.5

  File "C:\Users\Lenovo\AppData\Local\Programs\Python\Python310\lib\socketserver.py", line 237, in serve_forever
    self._handle_request_noblock()
    │    └ <function BaseServer._handle_request_noblock at 0x000001C68FBC7E20>
    └ <werkzeug.serving.BaseWSGIServer object at 0x000001C692291C00>

  File "C:\Users\Lenovo\AppData\Local\Programs\Python\Python310\lib\socketserver.py", line 316, in _handle_request_noblock
    self.process_request(request, client_address)
    │    │               │        └ ('127.0.0.1', 54724)
    │    │               └ <socket.socket fd=876, family=AddressFamily.AF_INET, type=SocketKind.SOCK_STREAM, proto=0, laddr=('127.0.0.1', 5000), raddr=(...
    │    └ <function BaseServer.process_request at 0x000001C691418040>
    └ <werkzeug.serving.BaseWSGIServer object at 0x000001C692291C00>

  File "C:\Users\Lenovo\AppData\Local\Programs\Python\Python310\lib\socketserver.py", line 347, in process_request
    self.finish_request(request, client_address)
    │    │              │        └ ('127.0.0.1', 54724)
    │    │              └ <socket.socket fd=876, family=AddressFamily.AF_INET, type=SocketKind.SOCK_STREAM, proto=0, laddr=('127.0.0.1', 5000), raddr=(...
    │    └ <function BaseServer.finish_request at 0x000001C691418160>
    └ <werkzeug.serving.BaseWSGIServer object at 0x000001C692291C00>

  File "C:\Users\Lenovo\AppData\Local\Programs\Python\Python310\lib\socketserver.py", line 360, in finish_request
    self.RequestHandlerClass(request, client_address, self)
    │    │                   │        │               └ <werkzeug.serving.BaseWSGIServer object at 0x000001C692291C00>
    │    │                   │        └ ('127.0.0.1', 54724)
    │    │                   └ <socket.socket fd=876, family=AddressFamily.AF_INET, type=SocketKind.SOCK_STREAM, proto=0, laddr=('127.0.0.1', 5000), raddr=(...
    │    └ <class 'werkzeug.serving.WSGIRequestHandler'>
    └ <werkzeug.serving.BaseWSGIServer object at 0x000001C692291C00>

  File "C:\Users\Lenovo\AppData\Local\Programs\Python\Python310\lib\socketserver.py", line 747, in __init__
    self.handle()
    │    └ <function WSGIRequestHandler.handle at 0x000001C69240D990>
    └ <werkzeug.serving.WSGIRequestHandler object at 0x000001C694A92A40>

  File "C:\Users\Lenovo\AppData\Local\Programs\Python\Python310\lib\site-packages\werkzeug\serving.py", line 390, in handle
    super().handle()

  File "C:\Users\Lenovo\AppData\Local\Programs\Python\Python310\lib\http\server.py", line 432, in handle
    self.handle_one_request()
    │    └ <function BaseHTTPRequestHandler.handle_one_request at 0x000001C691419870>
    └ <werkzeug.serving.WSGIRequestHandler object at 0x000001C694A92A40>

  File "C:\Users\Lenovo\AppData\Local\Programs\Python\Python310\lib\http\server.py", line 420, in handle_one_request
    method()
    └ <bound method WSGIRequestHandler.run_wsgi of <werkzeug.serving.WSGIRequestHandler object at 0x000001C694A92A40>>

  File "C:\Users\Lenovo\AppData\Local\Programs\Python\Python310\lib\site-packages\werkzeug\serving.py", line 362, in run_wsgi
    execute(self.server.app)
    │       │    │      └ <werkzeug.debug.DebuggedApplication object at 0x000001C694A92B00>
    │       │    └ <werkzeug.serving.BaseWSGIServer object at 0x000001C692291C00>
    │       └ <werkzeug.serving.WSGIRequestHandler object at 0x000001C694A92A40>
    └ <function WSGIRequestHandler.run_wsgi.<locals>.execute at 0x000001C694B7F520>

  File "C:\Users\Lenovo\AppData\Local\Programs\Python\Python310\lib\site-packages\werkzeug\serving.py", line 325, in execute
    for data in application_iter:
                └ <generator object DebuggedApplication.debug_application at 0x000001C69493B450>

  File "C:\Users\Lenovo\AppData\Local\Programs\Python\Python310\lib\site-packages\werkzeug\debug\__init__.py", line 330, in debug_application
    app_iter = self.app(environ, start_response)
               │    │   │        └ <function WSGIRequestHandler.run_wsgi.<locals>.start_response at 0x000001C694B7EDD0>
               │    │   └ {'wsgi.version': (1, 0), 'wsgi.url_scheme': 'http', 'wsgi.input': <_io.BufferedReader name=876>, 'wsgi.errors': <_io.TextIOWr...
               │    └ <Flask 'app'>
               └ <werkzeug.debug.DebuggedApplication object at 0x000001C694A92B00>

  File "C:\Users\Lenovo\AppData\Local\Programs\Python\Python310\lib\site-packages\flask\app.py", line 2213, in __call__
    return self.wsgi_app(environ, start_response)
           │    │        │        └ <function WSGIRequestHandler.run_wsgi.<locals>.start_response at 0x000001C694B7EDD0>
           │    │        └ {'wsgi.version': (1, 0), 'wsgi.url_scheme': 'http', 'wsgi.input': <_io.BufferedReader name=876>, 'wsgi.errors': <_io.TextIOWr...
           │    └ <function Flask.wsgi_app at 0x000001C692753B50>
           └ <Flask 'app'>

  File "C:\Users\Lenovo\AppData\Local\Programs\Python\Python310\lib\site-packages\flask\app.py", line 2190, in wsgi_app
    response = self.full_dispatch_request()
               │    └ <function Flask.full_dispatch_request at 0x000001C6927530A0>
               └ <Flask 'app'>

  File "C:\Users\Lenovo\AppData\Local\Programs\Python\Python310\lib\site-packages\flask\app.py", line 1484, in full_dispatch_request
    rv = self.dispatch_request()
         │    └ <function Flask.dispatch_request at 0x000001C692753010>
         └ <Flask 'app'>

  File "C:\Users\Lenovo\AppData\Local\Programs\Python\Python310\lib\site-packages\flask\app.py", line 1469, in dispatch_request
    return self.ensure_sync(self.view_functions[rule.endpoint])(**view_args)
           │    │           │    │              │    │            └ {}
           │    │           │    │              │    └ 'users.register'
           │    │           │    │              └ <Rule '/api_1_0/users/register' (OPTIONS, POST) -> users.register>
           │    │           │    └ {'static': <function Flask.__init__.<locals>.<lambda> at 0x000001C693352680>, 'apiversion.Apiversion': <function View.as_view...
           │    │           └ <Flask 'app'>
           │    └ <function Flask.ensure_sync at 0x000001C6927532E0>
           └ <Flask 'app'>

  File "C:\Users\Lenovo\PycharmProjects\api_project\api\api_1_0\usersResource\urls.py", line 21, in register
    return UsersOtherResource.register()
           │                  └ <classmethod(<function UsersOtherResource.register at 0x000001C694A73D00>)>
           └ <class 'api_1_0.usersResource.usersOtherResource.UsersOtherResource'>

  File "C:\Users\Lenovo\PycharmProjects\api_project\api\api_1_0\usersResource\usersOtherResource.py", line 52, in register
    res = UsersService.register(**kwargs)
          │            │          └ {'account': '22', 'password': '423'}
          │            └ <classmethod(<function UsersService.register at 0x000001C694A72F80>)>
          └ <class 'service.usersService.UsersService'>

> File "C:\Users\Lenovo\PycharmProjects\api_project\api\service\usersService.py", line 66, in register
    db.session.commit()
    │  │       └ <function scoped_session.commit at 0x000001C6932B79A0>
    │  └ <sqlalchemy.orm.scoping.scoped_session object at 0x000001C69290C160>
    └ <SQLAlchemy mysql+pymysql://root:***@127.0.0.1:3306/project_1?charset=utf8>

  File "C:\Users\Lenovo\AppData\Local\Programs\Python\Python310\lib\site-packages\sqlalchemy\orm\scoping.py", line 598, in commit
    return self._proxied.commit()
           │    └ <property object at 0x000001C6932C1DA0>
           └ <sqlalchemy.orm.scoping.scoped_session object at 0x000001C69290C160>

  File "C:\Users\Lenovo\AppData\Local\Programs\Python\Python310\lib\site-packages\sqlalchemy\orm\session.py", line 1969, in commit
    trans.commit(_to_root=True)
    │     └ <function SessionTransaction.commit at 0x000001C6932312D0>
    └ <sqlalchemy.orm.session.SessionTransaction object at 0x000001C693487880>

  File "<string>", line 2, in commit

  File "C:\Users\Lenovo\AppData\Local\Programs\Python\Python310\lib\site-packages\sqlalchemy\orm\state_changes.py", line 139, in _go
    ret_value = fn(self, *arg, **kw)
                │  │      │      └ {'_to_root': True}
                │  │      └ ()
                │  └ <sqlalchemy.orm.session.SessionTransaction object at 0x000001C693487880>
                └ <function SessionTransaction.commit at 0x000001C693231240>

  File "C:\Users\Lenovo\AppData\Local\Programs\Python\Python310\lib\site-packages\sqlalchemy\orm\session.py", line 1256, in commit
    self._prepare_impl()
    │    └ <function SessionTransaction._prepare_impl at 0x000001C6932311B0>
    └ <sqlalchemy.orm.session.SessionTransaction object at 0x000001C693487880>

  File "<string>", line 2, in _prepare_impl

  File "C:\Users\Lenovo\AppData\Local\Programs\Python\Python310\lib\site-packages\sqlalchemy\orm\state_changes.py", line 139, in _go
    ret_value = fn(self, *arg, **kw)
                │  │      │      └ {}
                │  │      └ ()
                │  └ <sqlalchemy.orm.session.SessionTransaction object at 0x000001C693487880>
                └ <function SessionTransaction._prepare_impl at 0x000001C693231090>

  File "C:\Users\Lenovo\AppData\Local\Programs\Python\Python310\lib\site-packages\sqlalchemy\orm\session.py", line 1231, in _prepare_impl
    self.session.flush()
    │    │       └ <function Session.flush at 0x000001C693233D90>
    │    └ <sqlalchemy.orm.session.Session object at 0x000001C694BC4220>
    └ <sqlalchemy.orm.session.SessionTransaction object at 0x000001C693487880>

  File "C:\Users\Lenovo\AppData\Local\Programs\Python\Python310\lib\site-packages\sqlalchemy\orm\session.py", line 4312, in flush
    self._flush(objects)
    │    │      └ None
    │    └ <function Session._flush at 0x000001C693233F40>
    └ <sqlalchemy.orm.session.Session object at 0x000001C694BC4220>

  File "C:\Users\Lenovo\AppData\Local\Programs\Python\Python310\lib\site-packages\sqlalchemy\orm\session.py", line 4447, in _flush
    with util.safe_reraise():
         │    └ <class 'sqlalchemy.util.langhelpers.safe_reraise'>
         └ <module 'sqlalchemy.util' from 'C:\\Users\\Lenovo\\AppData\\Local\\Programs\\Python\\Python310\\lib\\site-packages\\sqlalchem...

  File "C:\Users\Lenovo\AppData\Local\Programs\Python\Python310\lib\site-packages\sqlalchemy\util\langhelpers.py", line 146, in __exit__
    raise exc_value.with_traceback(exc_tb)
          │         │              └ <traceback object at 0x000001C694C2AC80>
          │         └ <method 'with_traceback' of 'BaseException' objects>
          └ DataError('(pymysql.err.DataError) (1264, "Out of range value for column \'UserID\' at row 1")')

  File "C:\Users\Lenovo\AppData\Local\Programs\Python\Python310\lib\site-packages\sqlalchemy\orm\session.py", line 4408, in _flush
    flush_context.execute()
    │             └ <function UOWTransaction.execute at 0x000001C693222170>
    └ <sqlalchemy.orm.unitofwork.UOWTransaction object at 0x000001C694BC69B0>

  File "C:\Users\Lenovo\AppData\Local\Programs\Python\Python310\lib\site-packages\sqlalchemy\orm\unitofwork.py", line 466, in execute
    rec.execute(self)
    │   │       └ <sqlalchemy.orm.unitofwork.UOWTransaction object at 0x000001C694BC69B0>
    │   └ <function SaveUpdateAll.execute at 0x000001C693222A70>
    └ SaveUpdateAll(Mapper[Users(users)])

  File "C:\Users\Lenovo\AppData\Local\Programs\Python\Python310\lib\site-packages\sqlalchemy\orm\unitofwork.py", line 642, in execute
    util.preloaded.orm_persistence.save_obj(
    │    │         │               └ <function save_obj at 0x000001C69320D000>
    │    │         └ <module 'sqlalchemy.orm.persistence' from 'C:\\Users\\Lenovo\\AppData\\Local\\Programs\\Python\\Python310\\lib\\site-packages...
    │    └ <module 'sqlalchemy.util.preloaded' from 'C:\\Users\\Lenovo\\AppData\\Local\\Programs\\Python\\Python310\\lib\\site-packages\...
    └ <module 'sqlalchemy.util' from 'C:\\Users\\Lenovo\\AppData\\Local\\Programs\\Python\\Python310\\lib\\site-packages\\sqlalchem...

  File "C:\Users\Lenovo\AppData\Local\Programs\Python\Python310\lib\site-packages\sqlalchemy\orm\persistence.py", line 93, in save_obj
    _emit_insert_statements(
    └ <function _emit_insert_statements at 0x000001C69320DA20>

  File "C:\Users\Lenovo\AppData\Local\Programs\Python\Python310\lib\site-packages\sqlalchemy\orm\persistence.py", line 1043, in _emit_insert_statements
    result = connection.execute(
             │          └ <function Connection.execute at 0x000001C692EF0DC0>
             └ <sqlalchemy.engine.base.Connection object at 0x000001C694BC45E0>

  File "C:\Users\Lenovo\AppData\Local\Programs\Python\Python310\lib\site-packages\sqlalchemy\engine\base.py", line 1416, in execute
    return meth(
           └ <bound method ClauseElement._execute_on_connection of <sqlalchemy.sql.dml.Insert object at 0x000001C694BC5F90>>

  File "C:\Users\Lenovo\AppData\Local\Programs\Python\Python310\lib\site-packages\sqlalchemy\sql\elements.py", line 516, in _execute_on_connection
    return connection._execute_clauseelement(
           │          └ <function Connection._execute_clauseelement at 0x000001C692EF1090>
           └ <sqlalchemy.engine.base.Connection object at 0x000001C694BC45E0>

  File "C:\Users\Lenovo\AppData\Local\Programs\Python\Python310\lib\site-packages\sqlalchemy\engine\base.py", line 1639, in _execute_clauseelement
    ret = self._execute_context(
          │    └ <function Connection._execute_context at 0x000001C692EF1240>
          └ <sqlalchemy.engine.base.Connection object at 0x000001C694BC45E0>

  File "C:\Users\Lenovo\AppData\Local\Programs\Python\Python310\lib\site-packages\sqlalchemy\engine\base.py", line 1848, in _execute_context
    return self._exec_single_context(
           │    └ <function Connection._exec_single_context at 0x000001C692EF12D0>
           └ <sqlalchemy.engine.base.Connection object at 0x000001C694BC45E0>

  File "C:\Users\Lenovo\AppData\Local\Programs\Python\Python310\lib\site-packages\sqlalchemy\engine\base.py", line 1988, in _exec_single_context
    self._handle_dbapi_exception(
    │    └ <function Connection._handle_dbapi_exception at 0x000001C692EF1510>
    └ <sqlalchemy.engine.base.Connection object at 0x000001C694BC45E0>

  File "C:\Users\Lenovo\AppData\Local\Programs\Python\Python310\lib\site-packages\sqlalchemy\engine\base.py", line 2343, in _handle_dbapi_exception
    raise sqlalchemy_exception.with_traceback(exc_info[2]) from e
          │                    │              │                 └ DataError(1264, "Out of range value for column 'UserID' at row 1")
          │                    │              └ (<class 'pymysql.err.DataError'>, DataError(1264, "Out of range value for column 'UserID' at row 1"), <traceback object at 0x...
          │                    └ <method 'with_traceback' of 'BaseException' objects>
          └ DataError('(pymysql.err.DataError) (1264, "Out of range value for column \'UserID\' at row 1")')

  File "C:\Users\Lenovo\AppData\Local\Programs\Python\Python310\lib\site-packages\sqlalchemy\engine\base.py", line 1969, in _exec_single_context
    self.dialect.do_execute(
    │    │       └ <function DefaultDialect.do_execute at 0x000001C692F944C0>
    │    └ <sqlalchemy.dialects.mysql.pymysql.MySQLDialect_pymysql object at 0x000001C6933456F0>
    └ <sqlalchemy.engine.base.Connection object at 0x000001C694BC45E0>

  File "C:\Users\Lenovo\AppData\Local\Programs\Python\Python310\lib\site-packages\sqlalchemy\engine\default.py", line 922, in do_execute
    cursor.execute(statement, parameters)
    │      │       │          └ {'UserID': 2023120122346132, 'UserName': None, 'RealName': None, 'Gender': None, 'IDCard': None, 'Email': None, 'Address': No...
    │      │       └ 'INSERT INTO users (`UserID`, `UserName`, `RealName`, `Gender`, `IDCard`, `Email`, `Address`, `Account`, `Password`) VALUES (...
    │      └ <function Cursor.execute at 0x000001C6934EADD0>
    └ <pymysql.cursors.Cursor object at 0x000001C694BC7B80>

  File "C:\Users\Lenovo\AppData\Local\Programs\Python\Python310\lib\site-packages\pymysql\cursors.py", line 158, in execute
    result = self._query(query)
             │    │      └ "INSERT INTO users (`UserID`, `UserName`, `RealName`, `Gender`, `IDCard`, `Email`, `Address`, `Account`, `Password`) VALUES (...
             │    └ <function Cursor._query at 0x000001C6934EB250>
             └ <pymysql.cursors.Cursor object at 0x000001C694BC7B80>

  File "C:\Users\Lenovo\AppData\Local\Programs\Python\Python310\lib\site-packages\pymysql\cursors.py", line 325, in _query
    conn.query(q)
    │    │     └ "INSERT INTO users (`UserID`, `UserName`, `RealName`, `Gender`, `IDCard`, `Email`, `Address`, `Account`, `Password`) VALUES (...
    │    └ <function Connection.query at 0x000001C693536560>
    └ <pymysql.connections.Connection object at 0x000001C694BC4A60>

  File "C:\Users\Lenovo\AppData\Local\Programs\Python\Python310\lib\site-packages\pymysql\connections.py", line 549, in query
    self._affected_rows = self._read_query_result(unbuffered=unbuffered)
    │    │                │    │                             └ False
    │    │                │    └ <function Connection._read_query_result at 0x000001C693536B90>
    │    │                └ <pymysql.connections.Connection object at 0x000001C694BC4A60>
    │    └ 0
    └ <pymysql.connections.Connection object at 0x000001C694BC4A60>

  File "C:\Users\Lenovo\AppData\Local\Programs\Python\Python310\lib\site-packages\pymysql\connections.py", line 779, in _read_query_result
    result.read()
    │      └ <function MySQLResult.read at 0x000001C693537370>
    └ <pymysql.connections.MySQLResult object at 0x000001C694A92EF0>

  File "C:\Users\Lenovo\AppData\Local\Programs\Python\Python310\lib\site-packages\pymysql\connections.py", line 1157, in read
    first_packet = self.connection._read_packet()
                   │    └ None
                   └ <pymysql.connections.MySQLResult object at 0x000001C694A92EF0>

  File "C:\Users\Lenovo\AppData\Local\Programs\Python\Python310\lib\site-packages\pymysql\connections.py", line 729, in _read_packet
    packet.raise_for_error()
    │      └ <function MysqlPacket.raise_for_error at 0x000001C693535120>
    └ <pymysql.protocol.MysqlPacket object at 0x000001C694BC65F0>

  File "C:\Users\Lenovo\AppData\Local\Programs\Python\Python310\lib\site-packages\pymysql\protocol.py", line 221, in raise_for_error
    err.raise_mysql_exception(self._data)
    │   │                     │    └ <member '_data' of 'MysqlPacket' objects>
    │   │                     └ <pymysql.protocol.MysqlPacket object at 0x000001C694BC65F0>
    │   └ <function raise_mysql_exception at 0x000001C693410550>
    └ <module 'pymysql.err' from 'C:\\Users\\Lenovo\\AppData\\Local\\Programs\\Python\\Python310\\lib\\site-packages\\pymysql\\err....

  File "C:\Users\Lenovo\AppData\Local\Programs\Python\Python310\lib\site-packages\pymysql\err.py", line 143, in raise_mysql_exception
    raise errorclass(errno, errval)
          │          │      └ "Out of range value for column 'UserID' at row 1"
          │          └ 1264
          └ <class 'pymysql.err.DataError'>

sqlalchemy.exc.DataError: (pymysql.err.DataError) (1264, "Out of range value for column 'UserID' at row 1")
[SQL: INSERT INTO users (`UserID`, `UserName`, `RealName`, `Gender`, `IDCard`, `Email`, `Address`, `Account`, `Password`) VALUES (%(UserID)s, %(UserName)s, %(RealName)s, %(Gender)s, %(IDCard)s, %(Email)s, %(Address)s, %(Account)s, %(Password)s)]
[parameters: {'UserID': 2023120122346132, 'UserName': None, 'RealName': None, 'Gender': None, 'IDCard': None, 'Email': None, 'Address': None, 'Account': '22', 'Password': '423'}]
(Background on this error at: https://sqlalche.me/e/20/9h9h)
