2024-01-05 17:55:55.440 | ERROR    | utils.loggings:exception:40 - (pymysql.err.DataError) (1264, "Out of range value for column 'UserID' at row 1")
[SQL: INSERT INTO users (`UserID`, `UserName`, `RealName`, `Gender`, `IDCard`, `Email`, `Address`, `Account`, `Password`) VALUES (%(UserID)s, %(UserName)s, %(RealName)s, %(Gender)s, %(IDCard)s, %(Email)s, %(Address)s, %(Account)s, %(Password)s)]
[parameters: {'UserID': 2024010517554678, 'UserName': 'hello1', 'RealName': None, 'Gender': None, 'IDCard': None, 'Email': '183@163.com', 'Address': None, 'Account': None, 'Password': '123456'}]
(Background on this error at: https://sqlalche.me/e/20/9h9h)
Traceback (most recent call last):

  File "D:\Python\Python39\lib\site-packages\sqlalchemy\engine\base.py", line 1969, in _exec_single_context
    self.dialect.do_execute(
    │    │       └ <function DefaultDialect.do_execute at 0x000002586B5BC3A0>
    │    └ <sqlalchemy.dialects.mysql.pymysql.MySQLDialect_pymysql object at 0x000002586B9C1A90>
    └ <sqlalchemy.engine.base.Connection object at 0x000002586D1922E0>

  File "D:\Python\Python39\lib\site-packages\sqlalchemy\engine\default.py", line 922, in do_execute
    cursor.execute(statement, parameters)
    │      │       │          └ {'UserID': 2024010517554678, 'UserName': 'hello1', 'RealName': None, 'Gender': None, 'IDCard': None, 'Email': '183@163.com', ...
    │      │       └ 'INSERT INTO users (`UserID`, `UserName`, `RealName`, `Gender`, `IDCard`, `Email`, `Address`, `Account`, `Password`) VALUES (...
    │      └ <function Cursor.execute at 0x000002586BB9D4C0>
    └ <pymysql.cursors.Cursor object at 0x000002586D192640>

  File "D:\Python\Python39\lib\site-packages\pymysql\cursors.py", line 158, in execute
    result = self._query(query)
             │    │      └ "INSERT INTO users (`UserID`, `UserName`, `RealName`, `Gender`, `IDCard`, `Email`, `Address`, `Account`, `Password`) VALUES (...
             │    └ <function Cursor._query at 0x000002586BB9D940>
             └ <pymysql.cursors.Cursor object at 0x000002586D192640>

  File "D:\Python\Python39\lib\site-packages\pymysql\cursors.py", line 325, in _query
    conn.query(q)
    │    │     └ "INSERT INTO users (`UserID`, `UserName`, `RealName`, `Gender`, `IDCard`, `Email`, `Address`, `Account`, `Password`) VALUES (...
    │    └ <function Connection.query at 0x000002586BBA79D0>
    └ <pymysql.connections.Connection object at 0x000002586D1923D0>

  File "D:\Python\Python39\lib\site-packages\pymysql\connections.py", line 549, in query
    self._affected_rows = self._read_query_result(unbuffered=unbuffered)
    │    │                │    │                             └ False
    │    │                │    └ <function Connection._read_query_result at 0x000002586BBA8040>
    │    │                └ <pymysql.connections.Connection object at 0x000002586D1923D0>
    │    └ 0
    └ <pymysql.connections.Connection object at 0x000002586D1923D0>

  File "D:\Python\Python39\lib\site-packages\pymysql\connections.py", line 779, in _read_query_result
    result.read()
    │      └ <function MySQLResult.read at 0x000002586BBA8820>
    └ <pymysql.connections.MySQLResult object at 0x000002586D1582E0>

  File "D:\Python\Python39\lib\site-packages\pymysql\connections.py", line 1157, in read
    first_packet = self.connection._read_packet()
                   │    └ None
                   └ <pymysql.connections.MySQLResult object at 0x000002586D1582E0>

  File "D:\Python\Python39\lib\site-packages\pymysql\connections.py", line 729, in _read_packet
    packet.raise_for_error()
    │      └ <function MysqlPacket.raise_for_error at 0x000002586BBA65E0>
    └ <pymysql.protocol.MysqlPacket object at 0x000002586D1C97F0>

  File "D:\Python\Python39\lib\site-packages\pymysql\protocol.py", line 221, in raise_for_error
    err.raise_mysql_exception(self._data)
    │   │                     │    └ <member '_data' of 'MysqlPacket' objects>
    │   │                     └ <pymysql.protocol.MysqlPacket object at 0x000002586D1C97F0>
    │   └ <function raise_mysql_exception at 0x000002586BA65D30>
    └ <module 'pymysql.err' from 'D:\\Python\\Python39\\lib\\site-packages\\pymysql\\err.py'>

  File "D:\Python\Python39\lib\site-packages\pymysql\err.py", line 143, in raise_mysql_exception
    raise errorclass(errno, errval)
          │          │      └ "Out of range value for column 'UserID' at row 1"
          │          └ 1264
          └ <class 'pymysql.err.DataError'>

pymysql.err.DataError: (1264, "Out of range value for column 'UserID' at row 1")


The above exception was the direct cause of the following exception:


Traceback (most recent call last):

  File "D:\Python\Python39\lib\threading.py", line 937, in _bootstrap
    self._bootstrap_inner()
    │    └ <function Thread._bootstrap_inner at 0x000002584AAD4670>
    └ <Thread(Thread-1, started daemon 16312)>

  File "D:\Python\Python39\lib\threading.py", line 980, in _bootstrap_inner
    self.run()
    │    └ <function Thread.run at 0x000002584AAD43A0>
    └ <Thread(Thread-1, started daemon 16312)>

  File "D:\Python\Python39\lib\threading.py", line 917, in run
    self._target(*self._args, **self._kwargs)
    │    │        │    │        │    └ {}
    │    │        │    │        └ <Thread(Thread-1, started daemon 16312)>
    │    │        │    └ ()
    │    │        └ <Thread(Thread-1, started daemon 16312)>
    │    └ <bound method BaseWSGIServer.serve_forever of <werkzeug.serving.BaseWSGIServer object at 0x000002586D0F0FA0>>
    └ <Thread(Thread-1, started daemon 16312)>

  File "D:\Python\Python39\lib\site-packages\werkzeug\serving.py", line 806, in serve_forever
    super().serve_forever(poll_interval=poll_interval)
                                        └ 0.5

  File "D:\Python\Python39\lib\socketserver.py", line 237, in serve_forever
    self._handle_request_noblock()
    │    └ <function BaseServer._handle_request_noblock at 0x000002586A606AF0>
    └ <werkzeug.serving.BaseWSGIServer object at 0x000002586D0F0FA0>

  File "D:\Python\Python39\lib\socketserver.py", line 316, in _handle_request_noblock
    self.process_request(request, client_address)
    │    │               │        └ ('127.0.0.1', 53770)
    │    │               └ <socket.socket fd=1016, family=AddressFamily.AF_INET, type=SocketKind.SOCK_STREAM, proto=0, laddr=('127.0.0.1', 5000), raddr=...
    │    └ <function BaseServer.process_request at 0x000002586A606CA0>
    └ <werkzeug.serving.BaseWSGIServer object at 0x000002586D0F0FA0>

  File "D:\Python\Python39\lib\socketserver.py", line 347, in process_request
    self.finish_request(request, client_address)
    │    │              │        └ ('127.0.0.1', 53770)
    │    │              └ <socket.socket fd=1016, family=AddressFamily.AF_INET, type=SocketKind.SOCK_STREAM, proto=0, laddr=('127.0.0.1', 5000), raddr=...
    │    └ <function BaseServer.finish_request at 0x000002586A606DC0>
    └ <werkzeug.serving.BaseWSGIServer object at 0x000002586D0F0FA0>

  File "D:\Python\Python39\lib\socketserver.py", line 360, in finish_request
    self.RequestHandlerClass(request, client_address, self)
    │    │                   │        │               └ <werkzeug.serving.BaseWSGIServer object at 0x000002586D0F0FA0>
    │    │                   │        └ ('127.0.0.1', 53770)
    │    │                   └ <socket.socket fd=1016, family=AddressFamily.AF_INET, type=SocketKind.SOCK_STREAM, proto=0, laddr=('127.0.0.1', 5000), raddr=...
    │    └ <class 'werkzeug.serving.WSGIRequestHandler'>
    └ <werkzeug.serving.BaseWSGIServer object at 0x000002586D0F0FA0>

  File "D:\Python\Python39\lib\socketserver.py", line 747, in __init__
    self.handle()
    │    └ <function WSGIRequestHandler.handle at 0x000002586A845550>
    └ <werkzeug.serving.WSGIRequestHandler object at 0x000002586D130CA0>

  File "D:\Python\Python39\lib\site-packages\werkzeug\serving.py", line 390, in handle
    super().handle()

  File "D:\Python\Python39\lib\http\server.py", line 425, in handle
    self.handle_one_request()
    │    └ <function BaseHTTPRequestHandler.handle_one_request at 0x000002586A732160>
    └ <werkzeug.serving.WSGIRequestHandler object at 0x000002586D130CA0>

  File "D:\Python\Python39\lib\http\server.py", line 413, in handle_one_request
    method()
    └ <bound method WSGIRequestHandler.run_wsgi of <werkzeug.serving.WSGIRequestHandler object at 0x000002586D130CA0>>

  File "D:\Python\Python39\lib\site-packages\werkzeug\serving.py", line 362, in run_wsgi
    execute(self.server.app)
    │       │    │      └ <werkzeug.debug.DebuggedApplication object at 0x000002586D0F0670>
    │       │    └ <werkzeug.serving.BaseWSGIServer object at 0x000002586D0F0FA0>
    │       └ <werkzeug.serving.WSGIRequestHandler object at 0x000002586D130CA0>
    └ <function WSGIRequestHandler.run_wsgi.<locals>.execute at 0x000002586D151E50>

  File "D:\Python\Python39\lib\site-packages\werkzeug\serving.py", line 325, in execute
    for data in application_iter:
                └ <generator object DebuggedApplication.debug_application at 0x000002586D14E970>

  File "D:\Python\Python39\lib\site-packages\werkzeug\debug\__init__.py", line 330, in debug_application
    app_iter = self.app(environ, start_response)
               │    │   │        └ <function WSGIRequestHandler.run_wsgi.<locals>.start_response at 0x000002586D151D30>
               │    │   └ {'wsgi.version': (1, 0), 'wsgi.url_scheme': 'http', 'wsgi.input': <_io.BufferedReader name=1016>, 'wsgi.errors': <_io.TextIOW...
               │    └ <Flask 'app'>
               └ <werkzeug.debug.DebuggedApplication object at 0x000002586D0F0670>

  File "D:\Python\Python39\lib\site-packages\flask\app.py", line 2213, in __call__
    return self.wsgi_app(environ, start_response)
           │    │        │        └ <function WSGIRequestHandler.run_wsgi.<locals>.start_response at 0x000002586D151D30>
           │    │        └ {'wsgi.version': (1, 0), 'wsgi.url_scheme': 'http', 'wsgi.input': <_io.BufferedReader name=1016>, 'wsgi.errors': <_io.TextIOW...
           │    └ <function Flask.wsgi_app at 0x000002586AD6B790>
           └ <Flask 'app'>

  File "D:\Python\Python39\lib\site-packages\flask\app.py", line 2190, in wsgi_app
    response = self.full_dispatch_request()
               │    └ <function Flask.full_dispatch_request at 0x000002586AD68CA0>
               └ <Flask 'app'>

  File "D:\Python\Python39\lib\site-packages\flask\app.py", line 1484, in full_dispatch_request
    rv = self.dispatch_request()
         │    └ <function Flask.dispatch_request at 0x000002586AD68C10>
         └ <Flask 'app'>

  File "D:\Python\Python39\lib\site-packages\flask\app.py", line 1469, in dispatch_request
    return self.ensure_sync(self.view_functions[rule.endpoint])(**view_args)
           │    │           │    │              │    │            └ {}
           │    │           │    │              │    └ 'users.register'
           │    │           │    │              └ <Rule '/users/register' (OPTIONS, POST) -> users.register>
           │    │           │    └ {'static': <function Flask.__init__.<locals>.<lambda> at 0x000002586B9A68B0>, 'apiversion.Apiversion': <function View.as_view...
           │    │           └ <Flask 'app'>
           │    └ <function Flask.ensure_sync at 0x000002586AD68EE0>
           └ <Flask 'app'>

  File "E:\code\backend\api\api_1_0\usersResource\urls.py", line 22, in register
    return UsersOtherResource.register()
           │                  └ <classmethod object at 0x000002586D08D2E0>
           └ <class 'api_1_0.usersResource.usersOtherResource.UsersOtherResource'>

  File "E:\code\backend\api\api_1_0\usersResource\usersOtherResource.py", line 54, in register
    res = UsersService.register(**kwargs)
          │            │          └ {'username': 'hello1', 'email': '183@163.com', 'password': '123456', 'configurePassword': '123456'}
          │            └ <classmethod object at 0x000002586CD90310>
          └ <class 'service.usersService.UsersService'>

> File "E:\code\backend\api\service\usersService.py", line 70, in register
    db.session.commit()
    │  │       └ <function scoped_session.commit at 0x000002586B91CDC0>
    │  └ <sqlalchemy.orm.scoping.scoped_session object at 0x000002586AD7B5E0>
    └ <SQLAlchemy mysql+pymysql://root:***@127.0.0.1:3306/ticketsys?charset=utf8>

  File "D:\Python\Python39\lib\site-packages\sqlalchemy\orm\scoping.py", line 598, in commit
    return self._proxied.commit()
           │    └ <property object at 0x000002586B92A810>
           └ <sqlalchemy.orm.scoping.scoped_session object at 0x000002586AD7B5E0>

  File "D:\Python\Python39\lib\site-packages\sqlalchemy\orm\session.py", line 1969, in commit
    trans.commit(_to_root=True)
    │     └ <function SessionTransaction.commit at 0x000002586B881040>
    └ <sqlalchemy.orm.session.SessionTransaction object at 0x000002586AE57080>

  File "<string>", line 2, in commit

  File "D:\Python\Python39\lib\site-packages\sqlalchemy\orm\state_changes.py", line 139, in _go
    ret_value = fn(self, *arg, **kw)
                │  │      │      └ {'_to_root': True}
                │  │      └ ()
                │  └ <sqlalchemy.orm.session.SessionTransaction object at 0x000002586AE57080>
                └ <function SessionTransaction.commit at 0x000002586B87DEE0>

  File "D:\Python\Python39\lib\site-packages\sqlalchemy\orm\session.py", line 1256, in commit
    self._prepare_impl()
    │    └ <function SessionTransaction._prepare_impl at 0x000002586B87DE50>
    └ <sqlalchemy.orm.session.SessionTransaction object at 0x000002586AE57080>

  File "<string>", line 2, in _prepare_impl

  File "D:\Python\Python39\lib\site-packages\sqlalchemy\orm\state_changes.py", line 139, in _go
    ret_value = fn(self, *arg, **kw)
                │  │      │      └ {}
                │  │      └ ()
                │  └ <sqlalchemy.orm.session.SessionTransaction object at 0x000002586AE57080>
                └ <function SessionTransaction._prepare_impl at 0x000002586B87DD30>

  File "D:\Python\Python39\lib\site-packages\sqlalchemy\orm\session.py", line 1231, in _prepare_impl
    self.session.flush()
    │    │       └ <function Session.flush at 0x000002586B889AF0>
    │    └ <sqlalchemy.orm.session.Session object at 0x000002586D1585E0>
    └ <sqlalchemy.orm.session.SessionTransaction object at 0x000002586AE57080>

  File "D:\Python\Python39\lib\site-packages\sqlalchemy\orm\session.py", line 4312, in flush
    self._flush(objects)
    │    │      └ None
    │    └ <function Session._flush at 0x000002586B889CA0>
    └ <sqlalchemy.orm.session.Session object at 0x000002586D1585E0>

  File "D:\Python\Python39\lib\site-packages\sqlalchemy\orm\session.py", line 4448, in _flush
    transaction.rollback(_capture_exception=True)
    │           └ <function SessionTransaction.rollback at 0x000002586B8811F0>
    └ <sqlalchemy.orm.session.SessionTransaction object at 0x000002586D1EB480>

  File "D:\Python\Python39\lib\site-packages\sqlalchemy\util\langhelpers.py", line 146, in __exit__
    raise exc_value.with_traceback(exc_tb)
          │         │              └ <traceback object at 0x000002586D1E82C0>
          │         └ <method 'with_traceback' of 'BaseException' objects>
          └ DataError('(pymysql.err.DataError) (1264, "Out of range value for column \'UserID\' at row 1")')

  File "D:\Python\Python39\lib\site-packages\sqlalchemy\orm\session.py", line 4408, in _flush
    flush_context.execute()
    │             └ <function UOWTransaction.execute at 0x000002586B86ADC0>
    └ <sqlalchemy.orm.unitofwork.UOWTransaction object at 0x000002586D1C9AF0>

  File "D:\Python\Python39\lib\site-packages\sqlalchemy\orm\unitofwork.py", line 466, in execute
    rec.execute(self)
    │   │       └ <sqlalchemy.orm.unitofwork.UOWTransaction object at 0x000002586D1C9AF0>
    │   └ <function SaveUpdateAll.execute at 0x000002586B876700>
    └ SaveUpdateAll(Mapper[Users(users)])

  File "D:\Python\Python39\lib\site-packages\sqlalchemy\orm\unitofwork.py", line 642, in execute
    util.preloaded.orm_persistence.save_obj(
    │    │         │               └ <function save_obj at 0x000002586B84ADC0>
    │    │         └ <module 'sqlalchemy.orm.persistence' from 'D:\\Python\\Python39\\lib\\site-packages\\sqlalchemy\\orm\\persistence.py'>
    │    └ <module 'sqlalchemy.util.preloaded' from 'D:\\Python\\Python39\\lib\\site-packages\\sqlalchemy\\util\\preloaded.py'>
    └ <module 'sqlalchemy.util' from 'D:\\Python\\Python39\\lib\\site-packages\\sqlalchemy\\util\\__init__.py'>

  File "D:\Python\Python39\lib\site-packages\sqlalchemy\orm\persistence.py", line 93, in save_obj
    _emit_insert_statements(
    └ <function _emit_insert_statements at 0x000002586B8573A0>

  File "D:\Python\Python39\lib\site-packages\sqlalchemy\orm\persistence.py", line 1043, in _emit_insert_statements
    result = connection.execute(
             │          └ <function Connection.execute at 0x000002586B4FF4C0>
             └ <sqlalchemy.engine.base.Connection object at 0x000002586D1922E0>

  File "D:\Python\Python39\lib\site-packages\sqlalchemy\engine\base.py", line 1416, in execute
    return meth(
           └ <bound method ClauseElement._execute_on_connection of <sqlalchemy.sql.dml.Insert object at 0x000002586D1C58E0>>

  File "D:\Python\Python39\lib\site-packages\sqlalchemy\sql\elements.py", line 516, in _execute_on_connection
    return connection._execute_clauseelement(
           │          └ <function Connection._execute_clauseelement at 0x000002586B4FF790>
           └ <sqlalchemy.engine.base.Connection object at 0x000002586D1922E0>

  File "D:\Python\Python39\lib\site-packages\sqlalchemy\engine\base.py", line 1639, in _execute_clauseelement
    ret = self._execute_context(
          │    └ <function Connection._execute_context at 0x000002586B4FF940>
          └ <sqlalchemy.engine.base.Connection object at 0x000002586D1922E0>

  File "D:\Python\Python39\lib\site-packages\sqlalchemy\engine\base.py", line 1848, in _execute_context
    return self._exec_single_context(
           │    └ <function Connection._exec_single_context at 0x000002586B4FF9D0>
           └ <sqlalchemy.engine.base.Connection object at 0x000002586D1922E0>

  File "D:\Python\Python39\lib\site-packages\sqlalchemy\engine\base.py", line 1988, in _exec_single_context
    self._handle_dbapi_exception(
    │    └ <function Connection._handle_dbapi_exception at 0x000002586B4FFC10>
    └ <sqlalchemy.engine.base.Connection object at 0x000002586D1922E0>

  File "D:\Python\Python39\lib\site-packages\sqlalchemy\engine\base.py", line 2343, in _handle_dbapi_exception
    raise sqlalchemy_exception.with_traceback(exc_info[2]) from e
          │                    │              │                 └ DataError(1264, "Out of range value for column 'UserID' at row 1")
          │                    │              └ (<class 'pymysql.err.DataError'>, DataError(1264, "Out of range value for column 'UserID' at row 1"), <traceback object at 0x...
          │                    └ <method 'with_traceback' of 'BaseException' objects>
          └ DataError('(pymysql.err.DataError) (1264, "Out of range value for column \'UserID\' at row 1")')

  File "D:\Python\Python39\lib\site-packages\sqlalchemy\engine\base.py", line 1969, in _exec_single_context
    self.dialect.do_execute(
    │    │       └ <function DefaultDialect.do_execute at 0x000002586B5BC3A0>
    │    └ <sqlalchemy.dialects.mysql.pymysql.MySQLDialect_pymysql object at 0x000002586B9C1A90>
    └ <sqlalchemy.engine.base.Connection object at 0x000002586D1922E0>

  File "D:\Python\Python39\lib\site-packages\sqlalchemy\engine\default.py", line 922, in do_execute
    cursor.execute(statement, parameters)
    │      │       │          └ {'UserID': 2024010517554678, 'UserName': 'hello1', 'RealName': None, 'Gender': None, 'IDCard': None, 'Email': '183@163.com', ...
    │      │       └ 'INSERT INTO users (`UserID`, `UserName`, `RealName`, `Gender`, `IDCard`, `Email`, `Address`, `Account`, `Password`) VALUES (...
    │      └ <function Cursor.execute at 0x000002586BB9D4C0>
    └ <pymysql.cursors.Cursor object at 0x000002586D192640>

  File "D:\Python\Python39\lib\site-packages\pymysql\cursors.py", line 158, in execute
    result = self._query(query)
             │    │      └ "INSERT INTO users (`UserID`, `UserName`, `RealName`, `Gender`, `IDCard`, `Email`, `Address`, `Account`, `Password`) VALUES (...
             │    └ <function Cursor._query at 0x000002586BB9D940>
             └ <pymysql.cursors.Cursor object at 0x000002586D192640>

  File "D:\Python\Python39\lib\site-packages\pymysql\cursors.py", line 325, in _query
    conn.query(q)
    │    │     └ "INSERT INTO users (`UserID`, `UserName`, `RealName`, `Gender`, `IDCard`, `Email`, `Address`, `Account`, `Password`) VALUES (...
    │    └ <function Connection.query at 0x000002586BBA79D0>
    └ <pymysql.connections.Connection object at 0x000002586D1923D0>

  File "D:\Python\Python39\lib\site-packages\pymysql\connections.py", line 549, in query
    self._affected_rows = self._read_query_result(unbuffered=unbuffered)
    │    │                │    │                             └ False
    │    │                │    └ <function Connection._read_query_result at 0x000002586BBA8040>
    │    │                └ <pymysql.connections.Connection object at 0x000002586D1923D0>
    │    └ 0
    └ <pymysql.connections.Connection object at 0x000002586D1923D0>

  File "D:\Python\Python39\lib\site-packages\pymysql\connections.py", line 779, in _read_query_result
    result.read()
    │      └ <function MySQLResult.read at 0x000002586BBA8820>
    └ <pymysql.connections.MySQLResult object at 0x000002586D1582E0>

  File "D:\Python\Python39\lib\site-packages\pymysql\connections.py", line 1157, in read
    first_packet = self.connection._read_packet()
                   │    └ None
                   └ <pymysql.connections.MySQLResult object at 0x000002586D1582E0>

  File "D:\Python\Python39\lib\site-packages\pymysql\connections.py", line 729, in _read_packet
    packet.raise_for_error()
    │      └ <function MysqlPacket.raise_for_error at 0x000002586BBA65E0>
    └ <pymysql.protocol.MysqlPacket object at 0x000002586D1C97F0>

  File "D:\Python\Python39\lib\site-packages\pymysql\protocol.py", line 221, in raise_for_error
    err.raise_mysql_exception(self._data)
    │   │                     │    └ <member '_data' of 'MysqlPacket' objects>
    │   │                     └ <pymysql.protocol.MysqlPacket object at 0x000002586D1C97F0>
    │   └ <function raise_mysql_exception at 0x000002586BA65D30>
    └ <module 'pymysql.err' from 'D:\\Python\\Python39\\lib\\site-packages\\pymysql\\err.py'>

  File "D:\Python\Python39\lib\site-packages\pymysql\err.py", line 143, in raise_mysql_exception
    raise errorclass(errno, errval)
          │          │      └ "Out of range value for column 'UserID' at row 1"
          │          └ 1264
          └ <class 'pymysql.err.DataError'>

sqlalchemy.exc.DataError: (pymysql.err.DataError) (1264, "Out of range value for column 'UserID' at row 1")
[SQL: INSERT INTO users (`UserID`, `UserName`, `RealName`, `Gender`, `IDCard`, `Email`, `Address`, `Account`, `Password`) VALUES (%(UserID)s, %(UserName)s, %(RealName)s, %(Gender)s, %(IDCard)s, %(Email)s, %(Address)s, %(Account)s, %(Password)s)]
[parameters: {'UserID': 2024010517554678, 'UserName': 'hello1', 'RealName': None, 'Gender': None, 'IDCard': None, 'Email': '183@163.com', 'Address': None, 'Account': None, 'Password': '123456'}]
(Background on this error at: https://sqlalche.me/e/20/9h9h)
2024-01-05 17:55:56.548 | ERROR    | utils.loggings:exception:40 - (pymysql.err.DataError) (1264, "Out of range value for column 'UserID' at row 1")
[SQL: INSERT INTO users (`UserID`, `UserName`, `RealName`, `Gender`, `IDCard`, `Email`, `Address`, `Account`, `Password`) VALUES (%(UserID)s, %(UserName)s, %(RealName)s, %(Gender)s, %(IDCard)s, %(Email)s, %(Address)s, %(Account)s, %(Password)s)]
[parameters: {'UserID': 2024010517558495, 'UserName': 'hello1', 'RealName': None, 'Gender': None, 'IDCard': None, 'Email': '183@163.com', 'Address': None, 'Account': None, 'Password': '123456'}]
(Background on this error at: https://sqlalche.me/e/20/9h9h)
Traceback (most recent call last):

  File "D:\Python\Python39\lib\site-packages\sqlalchemy\engine\base.py", line 1969, in _exec_single_context
    self.dialect.do_execute(
    │    │       └ <function DefaultDialect.do_execute at 0x000002586B5BC3A0>
    │    └ <sqlalchemy.dialects.mysql.pymysql.MySQLDialect_pymysql object at 0x000002586B9C1A90>
    └ <sqlalchemy.engine.base.Connection object at 0x000002586D538220>

  File "D:\Python\Python39\lib\site-packages\sqlalchemy\engine\default.py", line 922, in do_execute
    cursor.execute(statement, parameters)
    │      │       │          └ {'UserID': 2024010517558495, 'UserName': 'hello1', 'RealName': None, 'Gender': None, 'IDCard': None, 'Email': '183@163.com', ...
    │      │       └ 'INSERT INTO users (`UserID`, `UserName`, `RealName`, `Gender`, `IDCard`, `Email`, `Address`, `Account`, `Password`) VALUES (...
    │      └ <function Cursor.execute at 0x000002586BB9D4C0>
    └ <pymysql.cursors.Cursor object at 0x000002586D538490>

  File "D:\Python\Python39\lib\site-packages\pymysql\cursors.py", line 158, in execute
    result = self._query(query)
             │    │      └ "INSERT INTO users (`UserID`, `UserName`, `RealName`, `Gender`, `IDCard`, `Email`, `Address`, `Account`, `Password`) VALUES (...
             │    └ <function Cursor._query at 0x000002586BB9D940>
             └ <pymysql.cursors.Cursor object at 0x000002586D538490>

  File "D:\Python\Python39\lib\site-packages\pymysql\cursors.py", line 325, in _query
    conn.query(q)
    │    │     └ "INSERT INTO users (`UserID`, `UserName`, `RealName`, `Gender`, `IDCard`, `Email`, `Address`, `Account`, `Password`) VALUES (...
    │    └ <function Connection.query at 0x000002586BBA79D0>
    └ <pymysql.connections.Connection object at 0x000002586D1923D0>

  File "D:\Python\Python39\lib\site-packages\pymysql\connections.py", line 549, in query
    self._affected_rows = self._read_query_result(unbuffered=unbuffered)
    │    │                │    │                             └ False
    │    │                │    └ <function Connection._read_query_result at 0x000002586BBA8040>
    │    │                └ <pymysql.connections.Connection object at 0x000002586D1923D0>
    │    └ 0
    └ <pymysql.connections.Connection object at 0x000002586D1923D0>

  File "D:\Python\Python39\lib\site-packages\pymysql\connections.py", line 779, in _read_query_result
    result.read()
    │      └ <function MySQLResult.read at 0x000002586BBA8820>
    └ <pymysql.connections.MySQLResult object at 0x000002586D268DF0>

  File "D:\Python\Python39\lib\site-packages\pymysql\connections.py", line 1157, in read
    first_packet = self.connection._read_packet()
                   │    └ None
                   └ <pymysql.connections.MySQLResult object at 0x000002586D268DF0>

  File "D:\Python\Python39\lib\site-packages\pymysql\connections.py", line 729, in _read_packet
    packet.raise_for_error()
    │      └ <function MysqlPacket.raise_for_error at 0x000002586BBA65E0>
    └ <pymysql.protocol.MysqlPacket object at 0x000002586D538520>

  File "D:\Python\Python39\lib\site-packages\pymysql\protocol.py", line 221, in raise_for_error
    err.raise_mysql_exception(self._data)
    │   │                     │    └ <member '_data' of 'MysqlPacket' objects>
    │   │                     └ <pymysql.protocol.MysqlPacket object at 0x000002586D538520>
    │   └ <function raise_mysql_exception at 0x000002586BA65D30>
    └ <module 'pymysql.err' from 'D:\\Python\\Python39\\lib\\site-packages\\pymysql\\err.py'>

  File "D:\Python\Python39\lib\site-packages\pymysql\err.py", line 143, in raise_mysql_exception
    raise errorclass(errno, errval)
          │          │      └ "Out of range value for column 'UserID' at row 1"
          │          └ 1264
          └ <class 'pymysql.err.DataError'>

pymysql.err.DataError: (1264, "Out of range value for column 'UserID' at row 1")


The above exception was the direct cause of the following exception:


Traceback (most recent call last):

  File "D:\Python\Python39\lib\threading.py", line 937, in _bootstrap
    self._bootstrap_inner()
    │    └ <function Thread._bootstrap_inner at 0x000002584AAD4670>
    └ <Thread(Thread-1, started daemon 16312)>

  File "D:\Python\Python39\lib\threading.py", line 980, in _bootstrap_inner
    self.run()
    │    └ <function Thread.run at 0x000002584AAD43A0>
    └ <Thread(Thread-1, started daemon 16312)>

  File "D:\Python\Python39\lib\threading.py", line 917, in run
    self._target(*self._args, **self._kwargs)
    │    │        │    │        │    └ {}
    │    │        │    │        └ <Thread(Thread-1, started daemon 16312)>
    │    │        │    └ ()
    │    │        └ <Thread(Thread-1, started daemon 16312)>
    │    └ <bound method BaseWSGIServer.serve_forever of <werkzeug.serving.BaseWSGIServer object at 0x000002586D0F0FA0>>
    └ <Thread(Thread-1, started daemon 16312)>

  File "D:\Python\Python39\lib\site-packages\werkzeug\serving.py", line 806, in serve_forever
    super().serve_forever(poll_interval=poll_interval)
                                        └ 0.5

  File "D:\Python\Python39\lib\socketserver.py", line 237, in serve_forever
    self._handle_request_noblock()
    │    └ <function BaseServer._handle_request_noblock at 0x000002586A606AF0>
    └ <werkzeug.serving.BaseWSGIServer object at 0x000002586D0F0FA0>

  File "D:\Python\Python39\lib\socketserver.py", line 316, in _handle_request_noblock
    self.process_request(request, client_address)
    │    │               │        └ ('127.0.0.1', 53773)
    │    │               └ <socket.socket fd=1016, family=AddressFamily.AF_INET, type=SocketKind.SOCK_STREAM, proto=0, laddr=('127.0.0.1', 5000), raddr=...
    │    └ <function BaseServer.process_request at 0x000002586A606CA0>
    └ <werkzeug.serving.BaseWSGIServer object at 0x000002586D0F0FA0>

  File "D:\Python\Python39\lib\socketserver.py", line 347, in process_request
    self.finish_request(request, client_address)
    │    │              │        └ ('127.0.0.1', 53773)
    │    │              └ <socket.socket fd=1016, family=AddressFamily.AF_INET, type=SocketKind.SOCK_STREAM, proto=0, laddr=('127.0.0.1', 5000), raddr=...
    │    └ <function BaseServer.finish_request at 0x000002586A606DC0>
    └ <werkzeug.serving.BaseWSGIServer object at 0x000002586D0F0FA0>

  File "D:\Python\Python39\lib\socketserver.py", line 360, in finish_request
    self.RequestHandlerClass(request, client_address, self)
    │    │                   │        │               └ <werkzeug.serving.BaseWSGIServer object at 0x000002586D0F0FA0>
    │    │                   │        └ ('127.0.0.1', 53773)
    │    │                   └ <socket.socket fd=1016, family=AddressFamily.AF_INET, type=SocketKind.SOCK_STREAM, proto=0, laddr=('127.0.0.1', 5000), raddr=...
    │    └ <class 'werkzeug.serving.WSGIRequestHandler'>
    └ <werkzeug.serving.BaseWSGIServer object at 0x000002586D0F0FA0>

  File "D:\Python\Python39\lib\socketserver.py", line 747, in __init__
    self.handle()
    │    └ <function WSGIRequestHandler.handle at 0x000002586A845550>
    └ <werkzeug.serving.WSGIRequestHandler object at 0x000002586D192D60>

  File "D:\Python\Python39\lib\site-packages\werkzeug\serving.py", line 390, in handle
    super().handle()

  File "D:\Python\Python39\lib\http\server.py", line 425, in handle
    self.handle_one_request()
    │    └ <function BaseHTTPRequestHandler.handle_one_request at 0x000002586A732160>
    └ <werkzeug.serving.WSGIRequestHandler object at 0x000002586D192D60>

  File "D:\Python\Python39\lib\http\server.py", line 413, in handle_one_request
    method()
    └ <bound method WSGIRequestHandler.run_wsgi of <werkzeug.serving.WSGIRequestHandler object at 0x000002586D192D60>>

  File "D:\Python\Python39\lib\site-packages\werkzeug\serving.py", line 362, in run_wsgi
    execute(self.server.app)
    │       │    │      └ <werkzeug.debug.DebuggedApplication object at 0x000002586D0F0670>
    │       │    └ <werkzeug.serving.BaseWSGIServer object at 0x000002586D0F0FA0>
    │       └ <werkzeug.serving.WSGIRequestHandler object at 0x000002586D192D60>
    └ <function WSGIRequestHandler.run_wsgi.<locals>.execute at 0x000002586D4ABEE0>

  File "D:\Python\Python39\lib\site-packages\werkzeug\serving.py", line 325, in execute
    for data in application_iter:
                └ <generator object DebuggedApplication.debug_application at 0x000002586D51AF90>

  File "D:\Python\Python39\lib\site-packages\werkzeug\debug\__init__.py", line 330, in debug_application
    app_iter = self.app(environ, start_response)
               │    │   │        └ <function WSGIRequestHandler.run_wsgi.<locals>.start_response at 0x000002586D4ABF70>
               │    │   └ {'wsgi.version': (1, 0), 'wsgi.url_scheme': 'http', 'wsgi.input': <_io.BufferedReader name=1016>, 'wsgi.errors': <_io.TextIOW...
               │    └ <Flask 'app'>
               └ <werkzeug.debug.DebuggedApplication object at 0x000002586D0F0670>

  File "D:\Python\Python39\lib\site-packages\flask\app.py", line 2213, in __call__
    return self.wsgi_app(environ, start_response)
           │    │        │        └ <function WSGIRequestHandler.run_wsgi.<locals>.start_response at 0x000002586D4ABF70>
           │    │        └ {'wsgi.version': (1, 0), 'wsgi.url_scheme': 'http', 'wsgi.input': <_io.BufferedReader name=1016>, 'wsgi.errors': <_io.TextIOW...
           │    └ <function Flask.wsgi_app at 0x000002586AD6B790>
           └ <Flask 'app'>

  File "D:\Python\Python39\lib\site-packages\flask\app.py", line 2190, in wsgi_app
    response = self.full_dispatch_request()
               │    └ <function Flask.full_dispatch_request at 0x000002586AD68CA0>
               └ <Flask 'app'>

  File "D:\Python\Python39\lib\site-packages\flask\app.py", line 1484, in full_dispatch_request
    rv = self.dispatch_request()
         │    └ <function Flask.dispatch_request at 0x000002586AD68C10>
         └ <Flask 'app'>

  File "D:\Python\Python39\lib\site-packages\flask\app.py", line 1469, in dispatch_request
    return self.ensure_sync(self.view_functions[rule.endpoint])(**view_args)
           │    │           │    │              │    │            └ {}
           │    │           │    │              │    └ 'users.register'
           │    │           │    │              └ <Rule '/users/register' (OPTIONS, POST) -> users.register>
           │    │           │    └ {'static': <function Flask.__init__.<locals>.<lambda> at 0x000002586B9A68B0>, 'apiversion.Apiversion': <function View.as_view...
           │    │           └ <Flask 'app'>
           │    └ <function Flask.ensure_sync at 0x000002586AD68EE0>
           └ <Flask 'app'>

  File "E:\code\backend\api\api_1_0\usersResource\urls.py", line 22, in register
    return UsersOtherResource.register()
           │                  └ <classmethod object at 0x000002586D08D2E0>
           └ <class 'api_1_0.usersResource.usersOtherResource.UsersOtherResource'>

  File "E:\code\backend\api\api_1_0\usersResource\usersOtherResource.py", line 54, in register
    res = UsersService.register(**kwargs)
          │            │          └ {'username': 'hello1', 'email': '183@163.com', 'password': '123456', 'configurePassword': '123456'}
          │            └ <classmethod object at 0x000002586CD90310>
          └ <class 'service.usersService.UsersService'>

> File "E:\code\backend\api\service\usersService.py", line 70, in register
    db.session.commit()
    │  │       └ <function scoped_session.commit at 0x000002586B91CDC0>
    │  └ <sqlalchemy.orm.scoping.scoped_session object at 0x000002586AD7B5E0>
    └ <SQLAlchemy mysql+pymysql://root:***@127.0.0.1:3306/ticketsys?charset=utf8>

  File "D:\Python\Python39\lib\site-packages\sqlalchemy\orm\scoping.py", line 598, in commit
    return self._proxied.commit()
           │    └ <property object at 0x000002586B92A810>
           └ <sqlalchemy.orm.scoping.scoped_session object at 0x000002586AD7B5E0>

  File "D:\Python\Python39\lib\site-packages\sqlalchemy\orm\session.py", line 1969, in commit
    trans.commit(_to_root=True)
    │     └ <function SessionTransaction.commit at 0x000002586B881040>
    └ <sqlalchemy.orm.session.SessionTransaction object at 0x000002586D53C680>

  File "<string>", line 2, in commit

  File "D:\Python\Python39\lib\site-packages\sqlalchemy\orm\state_changes.py", line 139, in _go
    ret_value = fn(self, *arg, **kw)
                │  │      │      └ {'_to_root': True}
                │  │      └ ()
                │  └ <sqlalchemy.orm.session.SessionTransaction object at 0x000002586D53C680>
                └ <function SessionTransaction.commit at 0x000002586B87DEE0>

  File "D:\Python\Python39\lib\site-packages\sqlalchemy\orm\session.py", line 1256, in commit
    self._prepare_impl()
    │    └ <function SessionTransaction._prepare_impl at 0x000002586B87DE50>
    └ <sqlalchemy.orm.session.SessionTransaction object at 0x000002586D53C680>

  File "<string>", line 2, in _prepare_impl

  File "D:\Python\Python39\lib\site-packages\sqlalchemy\orm\state_changes.py", line 139, in _go
    ret_value = fn(self, *arg, **kw)
                │  │      │      └ {}
                │  │      └ ()
                │  └ <sqlalchemy.orm.session.SessionTransaction object at 0x000002586D53C680>
                └ <function SessionTransaction._prepare_impl at 0x000002586B87DD30>

  File "D:\Python\Python39\lib\site-packages\sqlalchemy\orm\session.py", line 1231, in _prepare_impl
    self.session.flush()
    │    │       └ <function Session.flush at 0x000002586B889AF0>
    │    └ <sqlalchemy.orm.session.Session object at 0x000002586D268D90>
    └ <sqlalchemy.orm.session.SessionTransaction object at 0x000002586D53C680>

  File "D:\Python\Python39\lib\site-packages\sqlalchemy\orm\session.py", line 4312, in flush
    self._flush(objects)
    │    │      └ None
    │    └ <function Session._flush at 0x000002586B889CA0>
    └ <sqlalchemy.orm.session.Session object at 0x000002586D268D90>

  File "D:\Python\Python39\lib\site-packages\sqlalchemy\orm\session.py", line 4448, in _flush
    transaction.rollback(_capture_exception=True)
    │           └ <function SessionTransaction.rollback at 0x000002586B8811F0>
    └ <sqlalchemy.orm.session.SessionTransaction object at 0x000002586D53CE80>

  File "D:\Python\Python39\lib\site-packages\sqlalchemy\util\langhelpers.py", line 146, in __exit__
    raise exc_value.with_traceback(exc_tb)
          │         │              └ <traceback object at 0x000002586D53B680>
          │         └ <method 'with_traceback' of 'BaseException' objects>
          └ DataError('(pymysql.err.DataError) (1264, "Out of range value for column \'UserID\' at row 1")')

  File "D:\Python\Python39\lib\site-packages\sqlalchemy\orm\session.py", line 4408, in _flush
    flush_context.execute()
    │             └ <function UOWTransaction.execute at 0x000002586B86ADC0>
    └ <sqlalchemy.orm.unitofwork.UOWTransaction object at 0x000002586D268E80>

  File "D:\Python\Python39\lib\site-packages\sqlalchemy\orm\unitofwork.py", line 466, in execute
    rec.execute(self)
    │   │       └ <sqlalchemy.orm.unitofwork.UOWTransaction object at 0x000002586D268E80>
    │   └ <function SaveUpdateAll.execute at 0x000002586B876700>
    └ SaveUpdateAll(Mapper[Users(users)])

  File "D:\Python\Python39\lib\site-packages\sqlalchemy\orm\unitofwork.py", line 642, in execute
    util.preloaded.orm_persistence.save_obj(
    │    │         │               └ <function save_obj at 0x000002586B84ADC0>
    │    │         └ <module 'sqlalchemy.orm.persistence' from 'D:\\Python\\Python39\\lib\\site-packages\\sqlalchemy\\orm\\persistence.py'>
    │    └ <module 'sqlalchemy.util.preloaded' from 'D:\\Python\\Python39\\lib\\site-packages\\sqlalchemy\\util\\preloaded.py'>
    └ <module 'sqlalchemy.util' from 'D:\\Python\\Python39\\lib\\site-packages\\sqlalchemy\\util\\__init__.py'>

  File "D:\Python\Python39\lib\site-packages\sqlalchemy\orm\persistence.py", line 93, in save_obj
    _emit_insert_statements(
    └ <function _emit_insert_statements at 0x000002586B8573A0>

  File "D:\Python\Python39\lib\site-packages\sqlalchemy\orm\persistence.py", line 1043, in _emit_insert_statements
    result = connection.execute(
             │          └ <function Connection.execute at 0x000002586B4FF4C0>
             └ <sqlalchemy.engine.base.Connection object at 0x000002586D538220>

  File "D:\Python\Python39\lib\site-packages\sqlalchemy\engine\base.py", line 1416, in execute
    return meth(
           └ <bound method ClauseElement._execute_on_connection of <sqlalchemy.sql.dml.Insert object at 0x000002586D1C58E0>>

  File "D:\Python\Python39\lib\site-packages\sqlalchemy\sql\elements.py", line 516, in _execute_on_connection
    return connection._execute_clauseelement(
           │          └ <function Connection._execute_clauseelement at 0x000002586B4FF790>
           └ <sqlalchemy.engine.base.Connection object at 0x000002586D538220>

  File "D:\Python\Python39\lib\site-packages\sqlalchemy\engine\base.py", line 1639, in _execute_clauseelement
    ret = self._execute_context(
          │    └ <function Connection._execute_context at 0x000002586B4FF940>
          └ <sqlalchemy.engine.base.Connection object at 0x000002586D538220>

  File "D:\Python\Python39\lib\site-packages\sqlalchemy\engine\base.py", line 1848, in _execute_context
    return self._exec_single_context(
           │    └ <function Connection._exec_single_context at 0x000002586B4FF9D0>
           └ <sqlalchemy.engine.base.Connection object at 0x000002586D538220>

  File "D:\Python\Python39\lib\site-packages\sqlalchemy\engine\base.py", line 1988, in _exec_single_context
    self._handle_dbapi_exception(
    │    └ <function Connection._handle_dbapi_exception at 0x000002586B4FFC10>
    └ <sqlalchemy.engine.base.Connection object at 0x000002586D538220>

  File "D:\Python\Python39\lib\site-packages\sqlalchemy\engine\base.py", line 2343, in _handle_dbapi_exception
    raise sqlalchemy_exception.with_traceback(exc_info[2]) from e
          │                    │              │                 └ DataError(1264, "Out of range value for column 'UserID' at row 1")
          │                    │              └ (<class 'pymysql.err.DataError'>, DataError(1264, "Out of range value for column 'UserID' at row 1"), <traceback object at 0x...
          │                    └ <method 'with_traceback' of 'BaseException' objects>
          └ DataError('(pymysql.err.DataError) (1264, "Out of range value for column \'UserID\' at row 1")')

  File "D:\Python\Python39\lib\site-packages\sqlalchemy\engine\base.py", line 1969, in _exec_single_context
    self.dialect.do_execute(
    │    │       └ <function DefaultDialect.do_execute at 0x000002586B5BC3A0>
    │    └ <sqlalchemy.dialects.mysql.pymysql.MySQLDialect_pymysql object at 0x000002586B9C1A90>
    └ <sqlalchemy.engine.base.Connection object at 0x000002586D538220>

  File "D:\Python\Python39\lib\site-packages\sqlalchemy\engine\default.py", line 922, in do_execute
    cursor.execute(statement, parameters)
    │      │       │          └ {'UserID': 2024010517558495, 'UserName': 'hello1', 'RealName': None, 'Gender': None, 'IDCard': None, 'Email': '183@163.com', ...
    │      │       └ 'INSERT INTO users (`UserID`, `UserName`, `RealName`, `Gender`, `IDCard`, `Email`, `Address`, `Account`, `Password`) VALUES (...
    │      └ <function Cursor.execute at 0x000002586BB9D4C0>
    └ <pymysql.cursors.Cursor object at 0x000002586D538490>

  File "D:\Python\Python39\lib\site-packages\pymysql\cursors.py", line 158, in execute
    result = self._query(query)
             │    │      └ "INSERT INTO users (`UserID`, `UserName`, `RealName`, `Gender`, `IDCard`, `Email`, `Address`, `Account`, `Password`) VALUES (...
             │    └ <function Cursor._query at 0x000002586BB9D940>
             └ <pymysql.cursors.Cursor object at 0x000002586D538490>

  File "D:\Python\Python39\lib\site-packages\pymysql\cursors.py", line 325, in _query
    conn.query(q)
    │    │     └ "INSERT INTO users (`UserID`, `UserName`, `RealName`, `Gender`, `IDCard`, `Email`, `Address`, `Account`, `Password`) VALUES (...
    │    └ <function Connection.query at 0x000002586BBA79D0>
    └ <pymysql.connections.Connection object at 0x000002586D1923D0>

  File "D:\Python\Python39\lib\site-packages\pymysql\connections.py", line 549, in query
    self._affected_rows = self._read_query_result(unbuffered=unbuffered)
    │    │                │    │                             └ False
    │    │                │    └ <function Connection._read_query_result at 0x000002586BBA8040>
    │    │                └ <pymysql.connections.Connection object at 0x000002586D1923D0>
    │    └ 0
    └ <pymysql.connections.Connection object at 0x000002586D1923D0>

  File "D:\Python\Python39\lib\site-packages\pymysql\connections.py", line 779, in _read_query_result
    result.read()
    │      └ <function MySQLResult.read at 0x000002586BBA8820>
    └ <pymysql.connections.MySQLResult object at 0x000002586D268DF0>

  File "D:\Python\Python39\lib\site-packages\pymysql\connections.py", line 1157, in read
    first_packet = self.connection._read_packet()
                   │    └ None
                   └ <pymysql.connections.MySQLResult object at 0x000002586D268DF0>

  File "D:\Python\Python39\lib\site-packages\pymysql\connections.py", line 729, in _read_packet
    packet.raise_for_error()
    │      └ <function MysqlPacket.raise_for_error at 0x000002586BBA65E0>
    └ <pymysql.protocol.MysqlPacket object at 0x000002586D538520>

  File "D:\Python\Python39\lib\site-packages\pymysql\protocol.py", line 221, in raise_for_error
    err.raise_mysql_exception(self._data)
    │   │                     │    └ <member '_data' of 'MysqlPacket' objects>
    │   │                     └ <pymysql.protocol.MysqlPacket object at 0x000002586D538520>
    │   └ <function raise_mysql_exception at 0x000002586BA65D30>
    └ <module 'pymysql.err' from 'D:\\Python\\Python39\\lib\\site-packages\\pymysql\\err.py'>

  File "D:\Python\Python39\lib\site-packages\pymysql\err.py", line 143, in raise_mysql_exception
    raise errorclass(errno, errval)
          │          │      └ "Out of range value for column 'UserID' at row 1"
          │          └ 1264
          └ <class 'pymysql.err.DataError'>

sqlalchemy.exc.DataError: (pymysql.err.DataError) (1264, "Out of range value for column 'UserID' at row 1")
[SQL: INSERT INTO users (`UserID`, `UserName`, `RealName`, `Gender`, `IDCard`, `Email`, `Address`, `Account`, `Password`) VALUES (%(UserID)s, %(UserName)s, %(RealName)s, %(Gender)s, %(IDCard)s, %(Email)s, %(Address)s, %(Account)s, %(Password)s)]
[parameters: {'UserID': 2024010517558495, 'UserName': 'hello1', 'RealName': None, 'Gender': None, 'IDCard': None, 'Email': '183@163.com', 'Address': None, 'Account': None, 'Password': '123456'}]
(Background on this error at: https://sqlalche.me/e/20/9h9h)
2024-01-05 17:56:12.649 | ERROR    | utils.loggings:exception:40 - (pymysql.err.DataError) (1264, "Out of range value for column 'UserID' at row 1")
[SQL: INSERT INTO users (`UserID`, `UserName`, `RealName`, `Gender`, `IDCard`, `Email`, `Address`, `Account`, `Password`) VALUES (%(UserID)s, %(UserName)s, %(RealName)s, %(Gender)s, %(IDCard)s, %(Email)s, %(Address)s, %(Account)s, %(Password)s)]
[parameters: {'UserID': 2024010517569765, 'UserName': 'hello1', 'RealName': None, 'Gender': None, 'IDCard': None, 'Email': '183@163.com', 'Address': None, 'Account': None, 'Password': '123456'}]
(Background on this error at: https://sqlalche.me/e/20/9h9h)
Traceback (most recent call last):

  File "D:\Python\Python39\lib\site-packages\sqlalchemy\engine\base.py", line 1969, in _exec_single_context
    self.dialect.do_execute(
    │    │       └ <function DefaultDialect.do_execute at 0x000002586B5BC3A0>
    │    └ <sqlalchemy.dialects.mysql.pymysql.MySQLDialect_pymysql object at 0x000002586B9C1A90>
    └ <sqlalchemy.engine.base.Connection object at 0x000002586D538DF0>

  File "D:\Python\Python39\lib\site-packages\sqlalchemy\engine\default.py", line 922, in do_execute
    cursor.execute(statement, parameters)
    │      │       │          └ {'UserID': 2024010517569765, 'UserName': 'hello1', 'RealName': None, 'Gender': None, 'IDCard': None, 'Email': '183@163.com', ...
    │      │       └ 'INSERT INTO users (`UserID`, `UserName`, `RealName`, `Gender`, `IDCard`, `Email`, `Address`, `Account`, `Password`) VALUES (...
    │      └ <function Cursor.execute at 0x000002586BB9D4C0>
    └ <pymysql.cursors.Cursor object at 0x000002586D538A60>

  File "D:\Python\Python39\lib\site-packages\pymysql\cursors.py", line 158, in execute
    result = self._query(query)
             │    │      └ "INSERT INTO users (`UserID`, `UserName`, `RealName`, `Gender`, `IDCard`, `Email`, `Address`, `Account`, `Password`) VALUES (...
             │    └ <function Cursor._query at 0x000002586BB9D940>
             └ <pymysql.cursors.Cursor object at 0x000002586D538A60>

  File "D:\Python\Python39\lib\site-packages\pymysql\cursors.py", line 325, in _query
    conn.query(q)
    │    │     └ "INSERT INTO users (`UserID`, `UserName`, `RealName`, `Gender`, `IDCard`, `Email`, `Address`, `Account`, `Password`) VALUES (...
    │    └ <function Connection.query at 0x000002586BBA79D0>
    └ <pymysql.connections.Connection object at 0x000002586D1923D0>

  File "D:\Python\Python39\lib\site-packages\pymysql\connections.py", line 549, in query
    self._affected_rows = self._read_query_result(unbuffered=unbuffered)
    │    │                │    │                             └ False
    │    │                │    └ <function Connection._read_query_result at 0x000002586BBA8040>
    │    │                └ <pymysql.connections.Connection object at 0x000002586D1923D0>
    │    └ 0
    └ <pymysql.connections.Connection object at 0x000002586D1923D0>

  File "D:\Python\Python39\lib\site-packages\pymysql\connections.py", line 779, in _read_query_result
    result.read()
    │      └ <function MySQLResult.read at 0x000002586BBA8820>
    └ <pymysql.connections.MySQLResult object at 0x000002586D538FA0>

  File "D:\Python\Python39\lib\site-packages\pymysql\connections.py", line 1157, in read
    first_packet = self.connection._read_packet()
                   │    └ None
                   └ <pymysql.connections.MySQLResult object at 0x000002586D538FA0>

  File "D:\Python\Python39\lib\site-packages\pymysql\connections.py", line 729, in _read_packet
    packet.raise_for_error()
    │      └ <function MysqlPacket.raise_for_error at 0x000002586BBA65E0>
    └ <pymysql.protocol.MysqlPacket object at 0x000002586D538B20>

  File "D:\Python\Python39\lib\site-packages\pymysql\protocol.py", line 221, in raise_for_error
    err.raise_mysql_exception(self._data)
    │   │                     │    └ <member '_data' of 'MysqlPacket' objects>
    │   │                     └ <pymysql.protocol.MysqlPacket object at 0x000002586D538B20>
    │   └ <function raise_mysql_exception at 0x000002586BA65D30>
    └ <module 'pymysql.err' from 'D:\\Python\\Python39\\lib\\site-packages\\pymysql\\err.py'>

  File "D:\Python\Python39\lib\site-packages\pymysql\err.py", line 143, in raise_mysql_exception
    raise errorclass(errno, errval)
          │          │      └ "Out of range value for column 'UserID' at row 1"
          │          └ 1264
          └ <class 'pymysql.err.DataError'>

pymysql.err.DataError: (1264, "Out of range value for column 'UserID' at row 1")


The above exception was the direct cause of the following exception:


Traceback (most recent call last):

  File "D:\Python\Python39\lib\threading.py", line 937, in _bootstrap
    self._bootstrap_inner()
    │    └ <function Thread._bootstrap_inner at 0x000002584AAD4670>
    └ <Thread(Thread-1, started daemon 16312)>

  File "D:\Python\Python39\lib\threading.py", line 980, in _bootstrap_inner
    self.run()
    │    └ <function Thread.run at 0x000002584AAD43A0>
    └ <Thread(Thread-1, started daemon 16312)>

  File "D:\Python\Python39\lib\threading.py", line 917, in run
    self._target(*self._args, **self._kwargs)
    │    │        │    │        │    └ {}
    │    │        │    │        └ <Thread(Thread-1, started daemon 16312)>
    │    │        │    └ ()
    │    │        └ <Thread(Thread-1, started daemon 16312)>
    │    └ <bound method BaseWSGIServer.serve_forever of <werkzeug.serving.BaseWSGIServer object at 0x000002586D0F0FA0>>
    └ <Thread(Thread-1, started daemon 16312)>

  File "D:\Python\Python39\lib\site-packages\werkzeug\serving.py", line 806, in serve_forever
    super().serve_forever(poll_interval=poll_interval)
                                        └ 0.5

  File "D:\Python\Python39\lib\socketserver.py", line 237, in serve_forever
    self._handle_request_noblock()
    │    └ <function BaseServer._handle_request_noblock at 0x000002586A606AF0>
    └ <werkzeug.serving.BaseWSGIServer object at 0x000002586D0F0FA0>

  File "D:\Python\Python39\lib\socketserver.py", line 316, in _handle_request_noblock
    self.process_request(request, client_address)
    │    │               │        └ ('127.0.0.1', 53781)
    │    │               └ <socket.socket fd=1060, family=AddressFamily.AF_INET, type=SocketKind.SOCK_STREAM, proto=0, laddr=('127.0.0.1', 5000), raddr=...
    │    └ <function BaseServer.process_request at 0x000002586A606CA0>
    └ <werkzeug.serving.BaseWSGIServer object at 0x000002586D0F0FA0>

  File "D:\Python\Python39\lib\socketserver.py", line 347, in process_request
    self.finish_request(request, client_address)
    │    │              │        └ ('127.0.0.1', 53781)
    │    │              └ <socket.socket fd=1060, family=AddressFamily.AF_INET, type=SocketKind.SOCK_STREAM, proto=0, laddr=('127.0.0.1', 5000), raddr=...
    │    └ <function BaseServer.finish_request at 0x000002586A606DC0>
    └ <werkzeug.serving.BaseWSGIServer object at 0x000002586D0F0FA0>

  File "D:\Python\Python39\lib\socketserver.py", line 360, in finish_request
    self.RequestHandlerClass(request, client_address, self)
    │    │                   │        │               └ <werkzeug.serving.BaseWSGIServer object at 0x000002586D0F0FA0>
    │    │                   │        └ ('127.0.0.1', 53781)
    │    │                   └ <socket.socket fd=1060, family=AddressFamily.AF_INET, type=SocketKind.SOCK_STREAM, proto=0, laddr=('127.0.0.1', 5000), raddr=...
    │    └ <class 'werkzeug.serving.WSGIRequestHandler'>
    └ <werkzeug.serving.BaseWSGIServer object at 0x000002586D0F0FA0>

  File "D:\Python\Python39\lib\socketserver.py", line 747, in __init__
    self.handle()
    │    └ <function WSGIRequestHandler.handle at 0x000002586A845550>
    └ <werkzeug.serving.WSGIRequestHandler object at 0x000002586CC62C70>

  File "D:\Python\Python39\lib\site-packages\werkzeug\serving.py", line 390, in handle
    super().handle()

  File "D:\Python\Python39\lib\http\server.py", line 425, in handle
    self.handle_one_request()
    │    └ <function BaseHTTPRequestHandler.handle_one_request at 0x000002586A732160>
    └ <werkzeug.serving.WSGIRequestHandler object at 0x000002586CC62C70>

  File "D:\Python\Python39\lib\http\server.py", line 413, in handle_one_request
    method()
    └ <bound method WSGIRequestHandler.run_wsgi of <werkzeug.serving.WSGIRequestHandler object at 0x000002586CC62C70>>

  File "D:\Python\Python39\lib\site-packages\werkzeug\serving.py", line 362, in run_wsgi
    execute(self.server.app)
    │       │    │      └ <werkzeug.debug.DebuggedApplication object at 0x000002586D0F0670>
    │       │    └ <werkzeug.serving.BaseWSGIServer object at 0x000002586D0F0FA0>
    │       └ <werkzeug.serving.WSGIRequestHandler object at 0x000002586CC62C70>
    └ <function WSGIRequestHandler.run_wsgi.<locals>.execute at 0x000002586D536670>

  File "D:\Python\Python39\lib\site-packages\werkzeug\serving.py", line 325, in execute
    for data in application_iter:
                └ <generator object DebuggedApplication.debug_application at 0x000002586D51AF90>

  File "D:\Python\Python39\lib\site-packages\werkzeug\debug\__init__.py", line 330, in debug_application
    app_iter = self.app(environ, start_response)
               │    │   │        └ <function WSGIRequestHandler.run_wsgi.<locals>.start_response at 0x000002586D536550>
               │    │   └ {'wsgi.version': (1, 0), 'wsgi.url_scheme': 'http', 'wsgi.input': <_io.BufferedReader name=1060>, 'wsgi.errors': <_io.TextIOW...
               │    └ <Flask 'app'>
               └ <werkzeug.debug.DebuggedApplication object at 0x000002586D0F0670>

  File "D:\Python\Python39\lib\site-packages\flask\app.py", line 2213, in __call__
    return self.wsgi_app(environ, start_response)
           │    │        │        └ <function WSGIRequestHandler.run_wsgi.<locals>.start_response at 0x000002586D536550>
           │    │        └ {'wsgi.version': (1, 0), 'wsgi.url_scheme': 'http', 'wsgi.input': <_io.BufferedReader name=1060>, 'wsgi.errors': <_io.TextIOW...
           │    └ <function Flask.wsgi_app at 0x000002586AD6B790>
           └ <Flask 'app'>

  File "D:\Python\Python39\lib\site-packages\flask\app.py", line 2190, in wsgi_app
    response = self.full_dispatch_request()
               │    └ <function Flask.full_dispatch_request at 0x000002586AD68CA0>
               └ <Flask 'app'>

  File "D:\Python\Python39\lib\site-packages\flask\app.py", line 1484, in full_dispatch_request
    rv = self.dispatch_request()
         │    └ <function Flask.dispatch_request at 0x000002586AD68C10>
         └ <Flask 'app'>

  File "D:\Python\Python39\lib\site-packages\flask\app.py", line 1469, in dispatch_request
    return self.ensure_sync(self.view_functions[rule.endpoint])(**view_args)
           │    │           │    │              │    │            └ {}
           │    │           │    │              │    └ 'users.register'
           │    │           │    │              └ <Rule '/users/register' (OPTIONS, POST) -> users.register>
           │    │           │    └ {'static': <function Flask.__init__.<locals>.<lambda> at 0x000002586B9A68B0>, 'apiversion.Apiversion': <function View.as_view...
           │    │           └ <Flask 'app'>
           │    └ <function Flask.ensure_sync at 0x000002586AD68EE0>
           └ <Flask 'app'>

  File "E:\code\backend\api\api_1_0\usersResource\urls.py", line 22, in register
    return UsersOtherResource.register()
           │                  └ <classmethod object at 0x000002586D08D2E0>
           └ <class 'api_1_0.usersResource.usersOtherResource.UsersOtherResource'>

  File "E:\code\backend\api\api_1_0\usersResource\usersOtherResource.py", line 54, in register
    res = UsersService.register(**kwargs)
          │            │          └ {'username': 'hello1', 'email': '183@163.com', 'password': '123456', 'configurePassword': '123456'}
          │            └ <classmethod object at 0x000002586CD90310>
          └ <class 'service.usersService.UsersService'>

> File "E:\code\backend\api\service\usersService.py", line 70, in register
    db.session.commit()
    │  │       └ <function scoped_session.commit at 0x000002586B91CDC0>
    │  └ <sqlalchemy.orm.scoping.scoped_session object at 0x000002586AD7B5E0>
    └ <SQLAlchemy mysql+pymysql://root:***@127.0.0.1:3306/ticketsys?charset=utf8>

  File "D:\Python\Python39\lib\site-packages\sqlalchemy\orm\scoping.py", line 598, in commit
    return self._proxied.commit()
           │    └ <property object at 0x000002586B92A810>
           └ <sqlalchemy.orm.scoping.scoped_session object at 0x000002586AD7B5E0>

  File "D:\Python\Python39\lib\site-packages\sqlalchemy\orm\session.py", line 1969, in commit
    trans.commit(_to_root=True)
    │     └ <function SessionTransaction.commit at 0x000002586B881040>
    └ <sqlalchemy.orm.session.SessionTransaction object at 0x000002586D54CF80>

  File "<string>", line 2, in commit

  File "D:\Python\Python39\lib\site-packages\sqlalchemy\orm\state_changes.py", line 139, in _go
    ret_value = fn(self, *arg, **kw)
                │  │      │      └ {'_to_root': True}
                │  │      └ ()
                │  └ <sqlalchemy.orm.session.SessionTransaction object at 0x000002586D54CF80>
                └ <function SessionTransaction.commit at 0x000002586B87DEE0>

  File "D:\Python\Python39\lib\site-packages\sqlalchemy\orm\session.py", line 1256, in commit
    self._prepare_impl()
    │    └ <function SessionTransaction._prepare_impl at 0x000002586B87DE50>
    └ <sqlalchemy.orm.session.SessionTransaction object at 0x000002586D54CF80>

  File "<string>", line 2, in _prepare_impl

  File "D:\Python\Python39\lib\site-packages\sqlalchemy\orm\state_changes.py", line 139, in _go
    ret_value = fn(self, *arg, **kw)
                │  │      │      └ {}
                │  │      └ ()
                │  └ <sqlalchemy.orm.session.SessionTransaction object at 0x000002586D54CF80>
                └ <function SessionTransaction._prepare_impl at 0x000002586B87DD30>

  File "D:\Python\Python39\lib\site-packages\sqlalchemy\orm\session.py", line 1231, in _prepare_impl
    self.session.flush()
    │    │       └ <function Session.flush at 0x000002586B889AF0>
    │    └ <sqlalchemy.orm.session.Session object at 0x000002586D538A90>
    └ <sqlalchemy.orm.session.SessionTransaction object at 0x000002586D54CF80>

  File "D:\Python\Python39\lib\site-packages\sqlalchemy\orm\session.py", line 4312, in flush
    self._flush(objects)
    │    │      └ None
    │    └ <function Session._flush at 0x000002586B889CA0>
    └ <sqlalchemy.orm.session.Session object at 0x000002586D538A90>

  File "D:\Python\Python39\lib\site-packages\sqlalchemy\orm\session.py", line 4448, in _flush
    transaction.rollback(_capture_exception=True)
    │           └ <function SessionTransaction.rollback at 0x000002586B8811F0>
    └ <sqlalchemy.orm.session.SessionTransaction object at 0x000002586D54C880>

  File "D:\Python\Python39\lib\site-packages\sqlalchemy\util\langhelpers.py", line 146, in __exit__
    raise exc_value.with_traceback(exc_tb)
          │         │              └ <traceback object at 0x000002586D54A2C0>
          │         └ <method 'with_traceback' of 'BaseException' objects>
          └ DataError('(pymysql.err.DataError) (1264, "Out of range value for column \'UserID\' at row 1")')

  File "D:\Python\Python39\lib\site-packages\sqlalchemy\orm\session.py", line 4408, in _flush
    flush_context.execute()
    │             └ <function UOWTransaction.execute at 0x000002586B86ADC0>
    └ <sqlalchemy.orm.unitofwork.UOWTransaction object at 0x000002586D538B80>

  File "D:\Python\Python39\lib\site-packages\sqlalchemy\orm\unitofwork.py", line 466, in execute
    rec.execute(self)
    │   │       └ <sqlalchemy.orm.unitofwork.UOWTransaction object at 0x000002586D538B80>
    │   └ <function SaveUpdateAll.execute at 0x000002586B876700>
    └ SaveUpdateAll(Mapper[Users(users)])

  File "D:\Python\Python39\lib\site-packages\sqlalchemy\orm\unitofwork.py", line 642, in execute
    util.preloaded.orm_persistence.save_obj(
    │    │         │               └ <function save_obj at 0x000002586B84ADC0>
    │    │         └ <module 'sqlalchemy.orm.persistence' from 'D:\\Python\\Python39\\lib\\site-packages\\sqlalchemy\\orm\\persistence.py'>
    │    └ <module 'sqlalchemy.util.preloaded' from 'D:\\Python\\Python39\\lib\\site-packages\\sqlalchemy\\util\\preloaded.py'>
    └ <module 'sqlalchemy.util' from 'D:\\Python\\Python39\\lib\\site-packages\\sqlalchemy\\util\\__init__.py'>

  File "D:\Python\Python39\lib\site-packages\sqlalchemy\orm\persistence.py", line 93, in save_obj
    _emit_insert_statements(
    └ <function _emit_insert_statements at 0x000002586B8573A0>

  File "D:\Python\Python39\lib\site-packages\sqlalchemy\orm\persistence.py", line 1043, in _emit_insert_statements
    result = connection.execute(
             │          └ <function Connection.execute at 0x000002586B4FF4C0>
             └ <sqlalchemy.engine.base.Connection object at 0x000002586D538DF0>

  File "D:\Python\Python39\lib\site-packages\sqlalchemy\engine\base.py", line 1416, in execute
    return meth(
           └ <bound method ClauseElement._execute_on_connection of <sqlalchemy.sql.dml.Insert object at 0x000002586D1C58E0>>

  File "D:\Python\Python39\lib\site-packages\sqlalchemy\sql\elements.py", line 516, in _execute_on_connection
    return connection._execute_clauseelement(
           │          └ <function Connection._execute_clauseelement at 0x000002586B4FF790>
           └ <sqlalchemy.engine.base.Connection object at 0x000002586D538DF0>

  File "D:\Python\Python39\lib\site-packages\sqlalchemy\engine\base.py", line 1639, in _execute_clauseelement
    ret = self._execute_context(
          │    └ <function Connection._execute_context at 0x000002586B4FF940>
          └ <sqlalchemy.engine.base.Connection object at 0x000002586D538DF0>

  File "D:\Python\Python39\lib\site-packages\sqlalchemy\engine\base.py", line 1848, in _execute_context
    return self._exec_single_context(
           │    └ <function Connection._exec_single_context at 0x000002586B4FF9D0>
           └ <sqlalchemy.engine.base.Connection object at 0x000002586D538DF0>

  File "D:\Python\Python39\lib\site-packages\sqlalchemy\engine\base.py", line 1988, in _exec_single_context
    self._handle_dbapi_exception(
    │    └ <function Connection._handle_dbapi_exception at 0x000002586B4FFC10>
    └ <sqlalchemy.engine.base.Connection object at 0x000002586D538DF0>

  File "D:\Python\Python39\lib\site-packages\sqlalchemy\engine\base.py", line 2343, in _handle_dbapi_exception
    raise sqlalchemy_exception.with_traceback(exc_info[2]) from e
          │                    │              │                 └ DataError(1264, "Out of range value for column 'UserID' at row 1")
          │                    │              └ (<class 'pymysql.err.DataError'>, DataError(1264, "Out of range value for column 'UserID' at row 1"), <traceback object at 0x...
          │                    └ <method 'with_traceback' of 'BaseException' objects>
          └ DataError('(pymysql.err.DataError) (1264, "Out of range value for column \'UserID\' at row 1")')

  File "D:\Python\Python39\lib\site-packages\sqlalchemy\engine\base.py", line 1969, in _exec_single_context
    self.dialect.do_execute(
    │    │       └ <function DefaultDialect.do_execute at 0x000002586B5BC3A0>
    │    └ <sqlalchemy.dialects.mysql.pymysql.MySQLDialect_pymysql object at 0x000002586B9C1A90>
    └ <sqlalchemy.engine.base.Connection object at 0x000002586D538DF0>

  File "D:\Python\Python39\lib\site-packages\sqlalchemy\engine\default.py", line 922, in do_execute
    cursor.execute(statement, parameters)
    │      │       │          └ {'UserID': 2024010517569765, 'UserName': 'hello1', 'RealName': None, 'Gender': None, 'IDCard': None, 'Email': '183@163.com', ...
    │      │       └ 'INSERT INTO users (`UserID`, `UserName`, `RealName`, `Gender`, `IDCard`, `Email`, `Address`, `Account`, `Password`) VALUES (...
    │      └ <function Cursor.execute at 0x000002586BB9D4C0>
    └ <pymysql.cursors.Cursor object at 0x000002586D538A60>

  File "D:\Python\Python39\lib\site-packages\pymysql\cursors.py", line 158, in execute
    result = self._query(query)
             │    │      └ "INSERT INTO users (`UserID`, `UserName`, `RealName`, `Gender`, `IDCard`, `Email`, `Address`, `Account`, `Password`) VALUES (...
             │    └ <function Cursor._query at 0x000002586BB9D940>
             └ <pymysql.cursors.Cursor object at 0x000002586D538A60>

  File "D:\Python\Python39\lib\site-packages\pymysql\cursors.py", line 325, in _query
    conn.query(q)
    │    │     └ "INSERT INTO users (`UserID`, `UserName`, `RealName`, `Gender`, `IDCard`, `Email`, `Address`, `Account`, `Password`) VALUES (...
    │    └ <function Connection.query at 0x000002586BBA79D0>
    └ <pymysql.connections.Connection object at 0x000002586D1923D0>

  File "D:\Python\Python39\lib\site-packages\pymysql\connections.py", line 549, in query
    self._affected_rows = self._read_query_result(unbuffered=unbuffered)
    │    │                │    │                             └ False
    │    │                │    └ <function Connection._read_query_result at 0x000002586BBA8040>
    │    │                └ <pymysql.connections.Connection object at 0x000002586D1923D0>
    │    └ 0
    └ <pymysql.connections.Connection object at 0x000002586D1923D0>

  File "D:\Python\Python39\lib\site-packages\pymysql\connections.py", line 779, in _read_query_result
    result.read()
    │      └ <function MySQLResult.read at 0x000002586BBA8820>
    └ <pymysql.connections.MySQLResult object at 0x000002586D538FA0>

  File "D:\Python\Python39\lib\site-packages\pymysql\connections.py", line 1157, in read
    first_packet = self.connection._read_packet()
                   │    └ None
                   └ <pymysql.connections.MySQLResult object at 0x000002586D538FA0>

  File "D:\Python\Python39\lib\site-packages\pymysql\connections.py", line 729, in _read_packet
    packet.raise_for_error()
    │      └ <function MysqlPacket.raise_for_error at 0x000002586BBA65E0>
    └ <pymysql.protocol.MysqlPacket object at 0x000002586D538B20>

  File "D:\Python\Python39\lib\site-packages\pymysql\protocol.py", line 221, in raise_for_error
    err.raise_mysql_exception(self._data)
    │   │                     │    └ <member '_data' of 'MysqlPacket' objects>
    │   │                     └ <pymysql.protocol.MysqlPacket object at 0x000002586D538B20>
    │   └ <function raise_mysql_exception at 0x000002586BA65D30>
    └ <module 'pymysql.err' from 'D:\\Python\\Python39\\lib\\site-packages\\pymysql\\err.py'>

  File "D:\Python\Python39\lib\site-packages\pymysql\err.py", line 143, in raise_mysql_exception
    raise errorclass(errno, errval)
          │          │      └ "Out of range value for column 'UserID' at row 1"
          │          └ 1264
          └ <class 'pymysql.err.DataError'>

sqlalchemy.exc.DataError: (pymysql.err.DataError) (1264, "Out of range value for column 'UserID' at row 1")
[SQL: INSERT INTO users (`UserID`, `UserName`, `RealName`, `Gender`, `IDCard`, `Email`, `Address`, `Account`, `Password`) VALUES (%(UserID)s, %(UserName)s, %(RealName)s, %(Gender)s, %(IDCard)s, %(Email)s, %(Address)s, %(Account)s, %(Password)s)]
[parameters: {'UserID': 2024010517569765, 'UserName': 'hello1', 'RealName': None, 'Gender': None, 'IDCard': None, 'Email': '183@163.com', 'Address': None, 'Account': None, 'Password': '123456'}]
(Background on this error at: https://sqlalche.me/e/20/9h9h)
